Workbook

Sheet Compare
A1: ICPC 2026 Asia EC — Nanjing (7–8 Nov) + Shenyang (14–15 Nov): 3 trip variants
A2: 3 contestants from Ulaanbaatar. Prices checked 30 Sep 2026; flights re-priced on Trip.com 30 Sep – 1 Oct 2026; trains (Ctrip) and hotels (Trip.com) re-checked 1 Oct; official fares and sale times from 12306 on 3 Oct. Blue = inputs; yellow = key assumptions; green = links to another sheet.
A4: Shared inputs
A5: University funding (MNT) | B5: 15000000 | C5: Given by team (raised from 12M on 30 Sep)
A6: Travelers | B6: 3 | C6: 3 contestants, no coach travelling
A7: USD → MNT | B7: 3598 | C7: Mid-market, Xe/Investing.com, 29–30 Sep 2026
A8: CNY → MNT | B8: 536 | C8: Mid-market, Xe/currency.wiki, late Sep 2026
A9: Contingency % | B9: 0.1 | C9: Buffer for fare changes, FX spread, extras
A11: Side-by-side
B12: A Balanced | C12: B Budget | D12: C Home between
A13: Subtotal (MNT) | B13: ='A Balanced'!H39 | C13: ='B Budget'!H39 | D13: ='C Home between'!H42
A14: Contingency | B14: ='A Balanced'!H40 | C14: ='B Budget'!H40 | D14: ='C Home between'!H43
A15: TOTAL incl. contingency | B15: ='A Balanced'!H41 | C15: ='B Budget'!H41 | D15: ='C Home between'!H44
A16: Funding left after subtotal (negative = over) | B16: ='A Balanced'!H44 | C16: ='B Budget'!H44 | D16: ='C Home between'!H47
A17: Out-of-pocket incl. contingency | B17: ='A Balanced'!H45 | C17: ='B Budget'!H45 | D17: ='C Home between'!H48
A18: Per person incl. contingency | B18: ='A Balanced'!H46 | C18: ='B Budget'!H46 | D18: ='C Home between'!H49
A19: Nights away from home | B19: 10 | C19: 10 | D19: 7 (home 10–13 Nov)
A20: Nanjing hotel → NUAA Jiangjun Rd | B20: ~1 km walk | C20: ~15 min metro | D20: ~1 km walk
A21: Shenyang hotel → NEU Nanhu | B21: ~1.3 km | C21: ~25 min metro | D21: ~1.3 km
A22: Beijing → Nanjing train | B22: Fast, ~3 h 25 min | C22: Slower, ~4 h 50 min | D22: Fast, both ways
A23: Main trade-off | B23: Best rest & least commuting on contest days; ~₮3.6M headroom | C23: Cheapest; subtotal fits even the original ₮12M; longer commutes, basic rooms | D23: Less class missed, sleep at home; ~4 extra travel legs; subtotal fits ₮15M but ~₮0.6M over once the 10% contingency is added
A25: Through tickets (checked 1 Oct) | B25: Single Air China tickets UB → Nanjing ($353), Nanjing → UB ($360–394) and Shenyang → UB ($286) all cost more than MIAT + high-speed rail, so all three variants keep separate tickets.
A26: New sources (checked 1 Oct) | B26: Ctrip train timetables: overnight K53/K54 sleepers Beijing ⇄ Shenyang (¥171 hard / ¥263 soft) replace a G-train + Beijing hotel night. Trip.com hotels near each venue (family rooms) undercut Booking.com.
A27: 12306 (checked 3 Oct) | B27: A and B: the Z366 overnight sleeper Nanjing 16:58 → Shenyang North 09:14 (hard ¥337 / soft ¥530) replaces the China Eastern flight ($121) and the 12 Nov Nanjing hotel night. ChinaTicketOnline resells the same trains at ~30–70% more once its $8.50–20 per-ticket fee is added – not used.

Sheet A Balanced
A1: A Balanced
A2: Hotels near both venues; fly MIAT via Beijing; high-speed rail; stay in Nanjing during the gap week.
A4: Variant inputs
A5: Days in China (meals & local transport) | B5: 10 | C5: Evening 6 Nov → morning 16 Nov
A6: Shared inputs (funding, FX, travelers, contingency) are on the Compare sheet.
A13: Category | B13: Item | C13: Date | D13: Unit cost | E13: Currency | F13: Qty | G13: Total (orig. ccy) | H13: Total (MNT) | I13: Source / notes
A14: Flights
B15: MIAT OM223 Ulaanbaatar → Beijing (PEK), nonstop 17:15–19:30 | C15: 6 Nov | D15: 150 | E15: USD | F15: =Compare!$B$6 | G15: =D15*F15 | H15: =G15*IF(E15="USD",Compare!$B$7,IF(E15="CNY",Compare!$B$8,1)) | I15: Trip.com 1 Oct: MIAT 17:15–19:30 $150 pp (SlickTrip 30 Sep: $154). Through tickets UB → Nanjing on 6 Nov cost more: Air China via Beijing $353, Spring/China Eastern via Shanghai $208 (no bag, lands 23:55)
B16: Air China Beijing (PEK) → Ulaanbaatar, nonstop 12:55–15:05 | C16: 16 Nov | D16: 171 | E16: USD | F16: =Compare!$B$6 | G16: =D16*F16 | H16: =G16*IF(E16="USD",Compare!$B$7,IF(E16="CNY",Compare!$B$8,1)) | I16: Trip.com 30 Sep: Air China nonstop $171 pp (MIAT OM224 11:30 was $194 on Trip.com, $196.33 on SlickTrip)
A17: Trains
B18: High-speed rail Beijing South → Nanjing South, fast G-train (~3 h 25 min) | C18: 7 Nov | D18: 504 | E18: CNY | F18: =Compare!$B$6 | G18: =D18*F18 | H18: =G18*IF(E18="USD",Compare!$B$7,IF(E18="CNY",Compare!$B$8,1)) | I18: Ctrip: 504 CNY on the ~3 h 23 min trains (slower ~4 h 50 min trains are 445)
B19: Overnight train Z366 Nanjing 16:58 → Shenyang North 09:14 (+1), soft sleeper (4-berth cabin) | C19: 12 Nov (night) | D19: 530 | E19: CNY | F19: =Compare!$B$6 | G19: =D19*F19 | H19: =G19*IF(E19="USD",Compare!$B$7,IF(E19="CNY",Compare!$B$8,1)) | I19: 12306 3 Oct (official fare, 15 Oct train): Z366 hard sleeper ¥337, soft ¥530. Replaces China Eastern 13 Nov 07:40 ($121) + the 12 Nov Nanjing hotel night, and lands at the same time. Sales open 29 Oct 08:15 (Nanjing station). Backups: Z516 18:38 → 10:26, Z176 18:32 → 10:42 (same fares); the China Eastern flight.
B20: Overnight train K54 Shenyang North 22:00 → Beijing 06:58, hard sleeper (after the contest) | C20: 15 Nov (night) | D20: 171 | E20: CNY | F20: =Compare!$B$6 | G20: =D20*F20 | H20: =G20*IF(E20="USD",Compare!$B$7,IF(E20="CNY",Compare!$B$8,1)) | I20: Ctrip 1 Oct / 12306: K54 hard sleeper ¥171 (soft ¥263). Hard on purpose: after the contest sleep no longer matters. Leaves 22:00, so a late closing ceremony is fine; replaces the evening G-train (¥339) + a Beijing hotel night. Air China through ticket SHE 09:00 → UB 15:05 ($286) is the fallback. Sales open 1 Nov 09:00 (Shenyang North).
A22: Accommodation (1 room for 3)
B23: Beijing budget hotel near Beijing South | C23: 6 Nov (1 night) | D23: 300 | E23: CNY | F23: 1 | G23: =D23*F23 | H23: =G23*IF(E23="USD",Compare!$B$7,IF(E23="CNY",Compare!$B$8,1)) | I23: Booking.com 6–7 Nov: 227–366 CNY/night for 3 people
B24: Mujiangnan Hotel, Cuipingshan (~1 km walk to NUAA Jiangjun Rd campus), Smart Family Room | C24: 7–12 Nov (5 nights) | D24: 251.33 | E24: CNY | F24: 5 | G24: =D24*F24 | H24: =G24*IF(E24="USD",Compare!$B$7,IF(E24="CNY",Compare!$B$8,1)) | I24: Trip.com 1 Oct: ¥1,508 for 6 nights (3 adults, 1 room); rated 9.2 (1,355 reviews). Was Magnotel ¥602.67/night. Plan books 5 of these nights; 12 Nov is on the Z366 sleeper.
B25: Shenyang RiCH Hotel, Sanhao St (~1.3 km to NEU Nanhu; Family Room sleeps 4) | C25: 13–15 Nov (2 nights) | D25: 338 | E25: CNY | F25: 2 | G25: =D25*F25 | H25: =G25*IF(E25="USD",Compare!$B$7,IF(E25="CNY",Compare!$B$8,1)) | I25: Trip.com 1 Oct: ¥676 for 2 nights (3 adults); rated 9.6 (1,802 reviews). Was Atour ¥524/night
A27: Contest fees
B28: Nanjing regional registration fee (per team) | C28: pay by mid-Oct | D28: 1500 | E28: CNY | F28: 1 | G28: =D28*F28 | H28: =G28*IF(E28="USD",Compare!$B$7,IF(E28="CNY",Compare!$B$8,1)) | I28: 1,500 CNY/team in 2023–2025 Nanjing guides; 2026 guide published 30 Sep – confirm
B29: Shenyang regional registration fee (per team) | C29: TBC | D29: 1500 | E29: CNY | F29: 1 | G29: =D29*F29 | H29: =G29*IF(E29="USD",Compare!$B$7,IF(E29="CNY",Compare!$B$8,1)) | I29: ASSUMPTION: same as Nanjing; 2026 Shenyang invitation not yet out
A30: Daily costs
B31: Meals (canteen / cheap restaurants) | C31: in China | D31: 80 | E31: CNY | F31: =Compare!$B$6*$B$5 | G31: =D31*F31 | H31: =G31*IF(E31="USD",Compare!$B$7,IF(E31="CNY",Compare!$B$8,1)) | I31: ASSUMPTION 80 CNY/person/day; hosts usually feed teams on contest days
B32: Local transport (metro, taxis, airport ↔ station) | C32: in China | D32: 30 | E32: CNY | F32: =Compare!$B$6*$B$5 | G32: =D32*F32 | H32: =G32*IF(E32="USD",Compare!$B$7,IF(E32="CNY",Compare!$B$8,1)) | I32: ASSUMPTION 30 CNY/person/day
A33: Other
B34: Taxi to/from Chinggis Khaan airport (UB) | C34: each airport trip | D34: 100000 | E34: MNT | F34: 2 | G34: =D34*F34 | H34: =G34*IF(E34="USD",Compare!$B$7,IF(E34="CNY",Compare!$B$8,1)) | I34: ASSUMPTION 100k MNT per trip for the group
B35: Travel medical insurance (per trip) | D35: 30000 | E35: MNT | F35: =Compare!$B$6 | G35: =D35*F35 | H35: =G35*IF(E35="USD",Compare!$B$7,IF(E35="CNY",Compare!$B$8,1)) | I35: ASSUMPTION ~30k MNT per person per trip, Mongolian insurer
B36: China mobile data eSIM | D36: 10 | E36: USD | F36: =Compare!$B$6 | G36: =D36*F36 | H36: =G36*IF(E36="USD",Compare!$B$7,IF(E36="CNY",Compare!$B$8,1)) | I36: ASSUMPTION ~$10 pp; needed for Alipay/WeChat Pay, maps
B37: China visa | D37: 0 | E37: MNT | F37: =Compare!$B$6 | G37: =D37*F37 | H37: =G37*IF(E37="USD",Compare!$B$7,IF(E37="CNY",Compare!$B$8,1)) | I37: Mongolian passports: visa-free up to 30 days – no cost
G39: Subtotal | H39: =SUM(H14:H37)
G40: Contingency | H40: =H39*Compare!$B$9
G41: TOTAL incl. contingency | H41: =H39+H40
G43: University funding | H43: =Compare!$B$5
G44: Funding left after subtotal (negative = over) | H44: =H43-H39
G45: Out-of-pocket incl. contingency | H45: =MAX(0,H41-H43)
G46: Per person incl. contingency | H46: =H41/Compare!$B$6
G48: By category
G49: Flights | H49: =SUMPRODUCT((LOOKUP(ROW(H14:H37),ROW(H14:H37)/(A14:A37<>""),A14:A37)="Flights")*H14:H37)
G50: Trains | H50: =SUMPRODUCT((LOOKUP(ROW(H14:H37),ROW(H14:H37)/(A14:A37<>""),A14:A37)="Trains")*H14:H37)
G51: Accommodation (1 room for 3) | H51: =SUMPRODUCT((LOOKUP(ROW(H14:H37),ROW(H14:H37)/(A14:A37<>""),A14:A37)="Accommodation (1 room for 3)")*H14:H37)
G52: Contest fees | H52: =SUMPRODUCT((LOOKUP(ROW(H14:H37),ROW(H14:H37)/(A14:A37<>""),A14:A37)="Contest fees")*H14:H37)
...

Sheet B Budget
A1: B Budget
A2: Cheapest found everything: hostels/budget chains farther from venues (metro commute), slower trains.
A4: Variant inputs
A5: Days in China (meals & local transport) | B5: 10 | C5: Evening 6 Nov → morning 16 Nov
A6: Shared inputs (funding, FX, travelers, contingency) are on the Compare sheet.
A13: Category | B13: Item | C13: Date | D13: Unit cost | E13: Currency | F13: Qty | G13: Total (orig. ccy) | H13: Total (MNT) | I13: Source / notes
A14: Flights
B15: MIAT OM223 Ulaanbaatar → Beijing (PEK), nonstop 17:15–19:30 | C15: 6 Nov | D15: 150 | E15: USD | F15: =Compare!$B$6 | G15: =D15*F15 | H15: =G15*IF(E15="USD",Compare!$B$7,IF(E15="CNY",Compare!$B$8,1)) | I15: Trip.com 1 Oct: MIAT 17:15–19:30 $150 pp (SlickTrip 30 Sep: $154). Through tickets UB → Nanjing on 6 Nov cost more: Air China via Beijing $353, Spring/China Eastern via Shanghai $208 (no bag, lands 23:55)
B16: Air China Beijing (PEK) → Ulaanbaatar, nonstop 12:55–15:05 | C16: 16 Nov | D16: 171 | E16: USD | F16: =Compare!$B$6 | G16: =D16*F16 | H16: =G16*IF(E16="USD",Compare!$B$7,IF(E16="CNY",Compare!$B$8,1)) | I16: Trip.com 30 Sep: Air China nonstop $171 pp (MIAT OM224 11:30 was $194 on Trip.com, $196.33 on SlickTrip)
A17: Trains
B18: High-speed rail Beijing South → Nanjing South, slower G-train (~4 h 35–50 min) | C18: 7 Nov | D18: 445 | E18: CNY | F18: =Compare!$B$6 | G18: =D18*F18 | H18: =G18*IF(E18="USD",Compare!$B$7,IF(E18="CNY",Compare!$B$8,1)) | I18: Ctrip: 445 CNY 2nd class
B19: Overnight train Z366 Nanjing 16:58 → Shenyang North 09:14 (+1), hard sleeper | C19: 12 Nov (night) | D19: 337 | E19: CNY | F19: =Compare!$B$6 | G19: =D19*F19 | H19: =G19*IF(E19="USD",Compare!$B$7,IF(E19="CNY",Compare!$B$8,1)) | I19: 12306 3 Oct (official fare, 15 Oct train): Z366 hard sleeper ¥337, soft ¥530. Replaces China Eastern 13 Nov 07:40 ($121) + the 12 Nov Nanjing hotel night, and lands at the same time. Sales open 29 Oct 08:15 (Nanjing station). Backups: Z516 18:38 → 10:26, Z176 18:32 → 10:42 (same fares); the China Eastern flight.
B20: Overnight train K54 Shenyang North 22:00 → Beijing 06:58, hard sleeper | C20: 15 Nov (night) | D20: 171 | E20: CNY | F20: =Compare!$B$6 | G20: =D20*F20 | H20: =G20*IF(E20="USD",Compare!$B$7,IF(E20="CNY",Compare!$B$8,1)) | I20: Ctrip 1 Oct: K54 hard sleeper ¥171, soft sleeper ¥263 (4-berth cabin). Leaves 22:00, so a late closing ceremony is fine; replaces the evening G-train (¥339) + a Beijing hotel night. Air China through ticket SHE 09:00 → UB 15:05 ($286) is the fallback. 12306 3 Oct: same official fares; sales open 1 Nov 09:00 (Shenyang North).
A22: Accommodation (1 room for 3)
B23: Beijing LeftBank Youth Hostel (Fengtai, near Beijing South) | C23: 6 Nov (1 night) | D23: 227 | E23: CNY | F23: 1 | G23: =D23*F23 | H23: =G23*IF(E23="USD",Compare!$B$7,IF(E23="CNY",Compare!$B$8,1)) | I23: Booking.com 6–7 Nov: 226.80 CNY for 3 people
B24: Pod Inn Nanjing South Station North Plaza (~3.8 km to NUAA, ~15 min metro), Family Room | C24: 7–12 Nov (5 nights) | D24: 109.67 | E24: CNY | F24: 5 | G24: =D24*F24 | H24: =G24*IF(E24="USD",Compare!$B$7,IF(E24="CNY",Compare!$B$8,1)) | I24: Trip.com 1 Oct: ¥658 for 6 nights (3 adults, 1 room); rated 8.4 (2,374 reviews). Was Jinjiang Inn Nanjing Station ¥145/night, ~50–60 min metro Plan books 5 of these nights; 12 Nov is on the Z366 sleeper.
B25: Bestay Hotel Express Shenyang (Huaiyuanmen; ~25 min metro to NEU Nanhu) | C25: 13–15 Nov (2 nights) | D25: 86 | E25: CNY | F25: 2 | G25: =D25*F25 | H25: =G25*IF(E25="USD",Compare!$B$7,IF(E25="CNY",Compare!$B$8,1)) | I25: Booking.com: 258 CNY for 3 nights = 86/night. Trip.com 1 Oct: rated 8.2 from 1,062 reviews – the low price is real
A27: Contest fees
B28: Nanjing regional registration fee (per team) | C28: pay by mid-Oct | D28: 1500 | E28: CNY | F28: 1 | G28: =D28*F28 | H28: =G28*IF(E28="USD",Compare!$B$7,IF(E28="CNY",Compare!$B$8,1)) | I28: 1,500 CNY/team in 2023–2025 Nanjing guides; 2026 guide published 30 Sep – confirm
B29: Shenyang regional registration fee (per team) | C29: TBC | D29: 1500 | E29: CNY | F29: 1 | G29: =D29*F29 | H29: =G29*IF(E29="USD",Compare!$B$7,IF(E29="CNY",Compare!$B$8,1)) | I29: ASSUMPTION: same as Nanjing; 2026 Shenyang invitation not yet out
A30: Daily costs
B31: Meals (canteen / cheap restaurants) | C31: in China | D31: 80 | E31: CNY | F31: =Compare!$B$6*$B$5 | G31: =D31*F31 | H31: =G31*IF(E31="USD",Compare!$B$7,IF(E31="CNY",Compare!$B$8,1)) | I31: ASSUMPTION 80 CNY/person/day; hosts usually feed teams on contest days
B32: Local transport (metro, taxis, airport ↔ station) | C32: in China | D32: 30 | E32: CNY | F32: =Compare!$B$6*$B$5 | G32: =D32*F32 | H32: =G32*IF(E32="USD",Compare!$B$7,IF(E32="CNY",Compare!$B$8,1)) | I32: ASSUMPTION 30 CNY/person/day
A33: Other
B34: Taxi to/from Chinggis Khaan airport (UB) | C34: each airport trip | D34: 100000 | E34: MNT | F34: 2 | G34: =D34*F34 | H34: =G34*IF(E34="USD",Compare!$B$7,IF(E34="CNY",Compare!$B$8,1)) | I34: ASSUMPTION 100k MNT per trip for the group
B35: Travel medical insurance (per trip) | D35: 30000 | E35: MNT | F35: =Compare!$B$6 | G35: =D35*F35 | H35: =G35*IF(E35="USD",Compare!$B$7,IF(E35="CNY",Compare!$B$8,1)) | I35: ASSUMPTION ~30k MNT per person per trip, Mongolian insurer
B36: China mobile data eSIM | D36: 10 | E36: USD | F36: =Compare!$B$6 | G36: =D36*F36 | H36: =G36*IF(E36="USD",Compare!$B$7,IF(E36="CNY",Compare!$B$8,1)) | I36: ASSUMPTION ~$10 pp; needed for Alipay/WeChat Pay, maps
B37: China visa | D37: 0 | E37: MNT | F37: =Compare!$B$6 | G37: =D37*F37 | H37: =G37*IF(E37="USD",Compare!$B$7,IF(E37="CNY",Compare!$B$8,1)) | I37: Mongolian passports: visa-free up to 30 days – no cost
G39: Subtotal | H39: =SUM(H14:H37)
G40: Contingency | H40: =H39*Compare!$B$9
G41: TOTAL incl. contingency | H41: =H39+H40
G43: University funding | H43: =Compare!$B$5
G44: Funding left after subtotal (negative = over) | H44: =H43-H39
G45: Out-of-pocket incl. contingency | H45: =MAX(0,H41-H43)
G46: Per person incl. contingency | H46: =H41/Compare!$B$6
G48: By category
G49: Flights | H49: =SUMPRODUCT((LOOKUP(ROW(H14:H37),ROW(H14:H37)/(A14:A37<>""),A14:A37)="Flights")*H14:H37)
G50: Trains | H50: =SUMPRODUCT((LOOKUP(ROW(H14:H37),ROW(H14:H37)/(A14:A37<>""),A14:A37)="Trains")*H14:H37)
G51: Accommodation (1 room for 3) | H51: =SUMPRODUCT((LOOKUP(ROW(H14:H37),ROW(H14:H37)/(A14:A37<>""),A14:A37)="Accommodation (1 room for 3)")*H14:H37)
G52: Contest fees | H52: =SUMPRODUCT((LOOKUP(ROW(H14:H37),ROW(H14:H37)/(A14:A37<>""),A14:A37)="Contest fees")*H14:H37)
...

Sheet C Home between
A1: C Home between
A2: Fly home to UB after Nanjing (10 Nov), back to China 13 Nov. Fewer days away, two extra flights.
A4: Variant inputs
A5: Days in China (meals & local transport) | B5: 7 | C5: 6–10 Nov + 13–16 Nov
A6: Shared inputs (funding, FX, travelers, contingency) are on the Compare sheet.
A13: Category | B13: Item | C13: Date | D13: Unit cost | E13: Currency | F13: Qty | G13: Total (orig. ccy) | H13: Total (MNT) | I13: Source / notes
A14: Flights
B15: MIAT OM223 Ulaanbaatar → Beijing (PEK), nonstop 17:15–19:30 | C15: 6 Nov | D15: 150 | E15: USD | F15: =Compare!$B$6 | G15: =D15*F15 | H15: =G15*IF(E15="USD",Compare!$B$7,IF(E15="CNY",Compare!$B$8,1)) | I15: Trip.com 1 Oct: MIAT 17:15–19:30 $150 pp (SlickTrip 30 Sep: $154). Through tickets UB → Nanjing on 6 Nov cost more: Air China via Beijing $353, Spring/China Eastern via Shanghai $208 (no bag, lands 23:55)
B16: MIAT OM224 Beijing (PEK) → Ulaanbaatar, 20:45–23:05 | C16: 10 Nov | D16: 219 | E16: USD | F16: =Compare!$B$6 | G16: =D16*F16 | H16: =G16*IF(E16="USD",Compare!$B$7,IF(E16="CNY",Compare!$B$8,1)) | I16: Trip.com 1 Oct: MIAT 20:45–23:05 $219 pp (SlickTrip $223). Air China 08:10 is $172 but needs an extra Beijing night on 9 Nov. Nanjing → UB in one ticket on 10 Nov costs more: $360–394 via Beijing (vs fast train $75 + MIAT $219)
B17: MIAT OM223 Ulaanbaatar → Beijing (PEK), 17:15–19:30 | C17: 13 Nov | D17: 150 | E17: USD | F17: =Compare!$B$6 | G17: =D17*F17 | H17: =G17*IF(E17="USD",Compare!$B$7,IF(E17="CNY",Compare!$B$8,1)) | I17: Trip.com 1 Oct: MIAT 17:15–19:30 $150 pp (SlickTrip 30 Sep: $154)
B18: Air China Beijing (PEK) → Ulaanbaatar, nonstop 12:55–15:05 | C18: 16 Nov | D18: 171 | E18: USD | F18: =Compare!$B$6 | G18: =D18*F18 | H18: =G18*IF(E18="USD",Compare!$B$7,IF(E18="CNY",Compare!$B$8,1)) | I18: Trip.com 30 Sep: Air China nonstop $171 pp (MIAT OM224 11:30 was $194 on Trip.com, $196.33 on SlickTrip)
A19: Trains
B20: High-speed rail Beijing South → Nanjing South, fast G-train (~3 h 25 min) | C20: 7 Nov | D20: 504 | E20: CNY | F20: =Compare!$B$6 | G20: =D20*F20 | H20: =G20*IF(E20="USD",Compare!$B$7,IF(E20="CNY",Compare!$B$8,1)) | I20: Ctrip: 504 CNY
B21: High-speed rail Nanjing South → Beijing South, fast G-train (~3 h 25 min) | C21: 10 Nov (midday) | D21: 504 | E21: CNY | F21: =Compare!$B$6 | G21: =D21*F21 | H21: =G21*IF(E21="USD",Compare!$B$7,IF(E21="CNY",Compare!$B$8,1)) | I21: Ctrip: 504 CNY; arrive Beijing late afternoon for 20:45 flight
B22: Overnight train K53 Beijing 22:35 → Shenyang North 07:00, soft sleeper | C22: 13 Nov (night) | D22: 263 | E22: CNY | F22: =Compare!$B$6 | G22: =D22*F22 | H22: =G22*IF(E22="USD",Compare!$B$7,IF(E22="CNY",Compare!$B$8,1)) | I22: Ctrip 1 Oct: K53 soft sleeper ¥263 (hard ¥171). Replaces the Beijing night + morning G-train (¥339). MIAT lands 19:30, so ~1 h 20 min spare after immigration + Airport Express; if MIAT is late, change the ticket (1 free change) to the 14 Nov G-train. 12306 3 Oct: same official fares; sales open 30 Oct 10:00 (Beijing station). Backup if K53 is sold out: K341 Beijing 23:00 → Shenyang 08:47, hard sleeper ¥194.
B23: Overnight train K54 Shenyang North 22:00 → Beijing 06:58, hard sleeper (after the contest) | C23: 15 Nov (night) | D23: 171 | E23: CNY | F23: =Compare!$B$6 | G23: =D23*F23 | H23: =G23*IF(E23="USD",Compare!$B$7,IF(E23="CNY",Compare!$B$8,1)) | I23: Ctrip 1 Oct / 12306: K54 hard sleeper ¥171 (soft ¥263). Hard on purpose: after the contest sleep no longer matters. Leaves 22:00, so a late closing ceremony is fine; replaces the evening G-train (¥339) + a Beijing hotel night. Air China through ticket SHE 09:00 → UB 15:05 ($286) is the fallback. Sales open 1 Nov 09:00 (Shenyang North).
A24: Accommodation (1 room for 3)
B25: Beijing budget hotel near Beijing South | C25: 6 Nov (1 night) | D25: 300 | E25: CNY | F25: 1 | G25: =D25*F25 | H25: =G25*IF(E25="USD",Compare!$B$7,IF(E25="CNY",Compare!$B$8,1)) | I25: Booking.com 6–7 Nov: 227–366 CNY/night
B26: Mujiangnan Hotel, Cuipingshan (~1 km walk to NUAA Jiangjun Rd campus), Smart Family Room | C26: 7–10 Nov (3 nights) | D26: 250.67 | E26: CNY | F26: 3 | G26: =D26*F26 | H26: =G26*IF(E26="USD",Compare!$B$7,IF(E26="CNY",Compare!$B$8,1)) | I26: Trip.com 1 Oct: ¥752 for 3 nights (3 adults, 1 room); rated 9.2 (1,355 reviews). Was Magnotel ¥602.67/night
B28: Shenyang RiCH Hotel, Sanhao St (~1.3 km to NEU Nanhu; Family Room sleeps 4) | C28: 14–15 Nov (1 night) | D28: 338 | E28: CNY | F28: 1 | G28: =D28*F28 | H28: =G28*IF(E28="USD",Compare!$B$7,IF(E28="CNY",Compare!$B$8,1)) | I28: Trip.com 1 Oct: ¥338 for 1 night (3 adults); rated 9.6 (1,802 reviews). Was Atour ¥524
A30: Contest fees
B31: Nanjing regional registration fee (per team) | C31: pay by mid-Oct | D31: 1500 | E31: CNY | F31: 1 | G31: =D31*F31 | H31: =G31*IF(E31="USD",Compare!$B$7,IF(E31="CNY",Compare!$B$8,1)) | I31: 1,500 CNY/team in 2023–2025 Nanjing guides; 2026 guide published 30 Sep – confirm
B32: Shenyang regional registration fee (per team) | C32: TBC | D32: 1500 | E32: CNY | F32: 1 | G32: =D32*F32 | H32: =G32*IF(E32="USD",Compare!$B$7,IF(E32="CNY",Compare!$B$8,1)) | I32: ASSUMPTION: same as Nanjing; 2026 Shenyang invitation not yet out
A33: Daily costs
B34: Meals (canteen / cheap restaurants) | C34: in China | D34: 80 | E34: CNY | F34: =Compare!$B$6*$B$5 | G34: =D34*F34 | H34: =G34*IF(E34="USD",Compare!$B$7,IF(E34="CNY",Compare!$B$8,1)) | I34: ASSUMPTION 80 CNY/person/day; hosts usually feed teams on contest days
B35: Local transport (metro, taxis, airport ↔ station) | C35: in China | D35: 30 | E35: CNY | F35: =Compare!$B$6*$B$5 | G35: =D35*F35 | H35: =G35*IF(E35="USD",Compare!$B$7,IF(E35="CNY",Compare!$B$8,1)) | I35: ASSUMPTION 30 CNY/person/day
A36: Other
B37: Taxi to/from Chinggis Khaan airport (UB) | C37: each airport trip | D37: 100000 | E37: MNT | F37: 4 | G37: =D37*F37 | H37: =G37*IF(E37="USD",Compare!$B$7,IF(E37="CNY",Compare!$B$8,1)) | I37: ASSUMPTION 100k MNT per trip for the group
B38: Travel medical insurance (per trip) | D38: 30000 | E38: MNT | F38: =Compare!$B$6*2 | G38: =D38*F38 | H38: =G38*IF(E38="USD",Compare!$B$7,IF(E38="CNY",Compare!$B$8,1)) | I38: ASSUMPTION ~30k MNT per person per trip, Mongolian insurer
B39: China mobile data eSIM | D39: 10 | E39: USD | F39: =Compare!$B$6 | G39: =D39*F39 | H39: =G39*IF(E39="USD",Compare!$B$7,IF(E39="CNY",Compare!$B$8,1)) | I39: ASSUMPTION ~$10 pp; needed for Alipay/WeChat Pay, maps
B40: China visa | D40: 0 | E40: MNT | F40: =Compare!$B$6 | G40: =D40*F40 | H40: =G40*IF(E40="USD",Compare!$B$7,IF(E40="CNY",Compare!$B$8,1)) | I40: Mongolian passports: visa-free up to 30 days – no cost
G42: Subtotal | H42: =SUM(H14:H40)
G43: Contingency | H43: =H42*Compare!$B$9
G44: TOTAL incl. contingency | H44: =H42+H43
G46: University funding | H46: =Compare!$B$5
G47: Funding left after subtotal (negative = over) | H47: =H46-H42
G48: Out-of-pocket incl. contingency | H48: =MAX(0,H44-H46)
G49: Per person incl. contingency | H49: =H44/Compare!$B$6
G51: By category
G52: Flights | H52: =SUMPRODUCT((LOOKUP(ROW(H14:H40),ROW(H14:H40)/(A14:A40<>""),A14:A40)="Flights")*H14:H40)
...

Sheet Itineraries
A1: A Balanced / B Budget (same route)
A2: Date | B2: Sleep in | C2: What happens
A3: Fri 6 Nov | B3: Beijing | C3: MIAT OM223 UB 17:15 → Beijing Capital 19:30. Hotel/hostel near Beijing South.
A4: Sat 7 Nov | B4: Nanjing | C4: Morning G-train Beijing South → Nanjing South (A: ~3 h 25 min fast train; B: ~4 h 50 min). Check-in & practice at NUAA Jiangjun Road campus. A: Mujiangnan Hotel (~1 km walk); B: Pod Inn (~15 min metro).
A5: Sun 8 Nov | B5: Nanjing | C5: NANJING REGIONAL contest day.
A6: 9–12 Nov | B6: Nanjing (12 Nov: train) | C6: Rest / upsolve / train in Nanjing. 12 Nov: check out, Z366 overnight sleeper Nanjing 16:58 → Shenyang North 09:14 (hard sleeper; after the contest).
A7: Fri 13 Nov | B7: Shenyang | C7: Arrive Shenyang North 09:14. Free day to rest; A: RiCH Hotel near NEU; B: Bestay.
A8: Sat 14 Nov | B8: Shenyang | C8: Check-in & practice at Northeastern University Nanhu campus.
A9: Sun 15 Nov | B9: Train | C9: SHENYANG REGIONAL contest day. K54 overnight sleeper Shenyang North 22:00 → Beijing 06:58 (hard sleeper; after the contest).
A10: Mon 16 Nov | B10: Home | C10: Beijing station → PEK by metro + Airport Express. Air China Beijing Capital 12:55 → UB 15:05 (nonstop).
A12: C Home between
A13: Date | B13: Sleep in | C13: What happens
A14: Fri 6 Nov | B14: Beijing | C14: MIAT OM223 UB 17:15 → Beijing 19:30.
A15: Sat 7 Nov | B15: Nanjing | C15: Fast G-train to Nanjing South. Check-in & practice at NUAA.
A16: Sun 8 Nov | B16: Nanjing | C16: NANJING REGIONAL contest day.
A17: Mon 9 Nov | B17: Nanjing | C17: Rest day in Nanjing (or leave a day early: 9 Nov MIAT 11:30 is $294.67 pp).
A18: Tue 10 Nov | B18: Home (late) | C18: Midday fast train Nanjing South → Beijing South; MIAT OM224 PEK 20:45 → UB 23:05.
A19: 11–12 Nov | B19: Home | C19: Classes / rest at home.
A20: Fri 13 Nov | B20: Train | C20: MIAT OM223 UB 17:15 → Beijing 19:30. Airport Express + metro to Beijing station; K53 soft sleeper 22:35 → Shenyang North 07:00.
A21: Sat 14 Nov | B21: Shenyang | C21: Arrive Shenyang 07:00, RiCH Hotel near NEU. Check-in & practice at NEU Nanhu.
A22: Sun 15 Nov | B22: Train | C22: SHENYANG REGIONAL contest day. K54 hard sleeper Shenyang North 22:00 → Beijing 06:58.
A23: Mon 16 Nov | B23: Home | C23: Beijing station → PEK by metro + Airport Express. Air China Beijing Capital 12:55 → UB 15:05 (nonstop).
A25: Note | C25: Dates are the organisers' provisional dates (ICPC Beijing HQ summary, 5 Aug 2026); venues are last year's campuses. Confirm both in each 2026 invitation before paying for anything non-refundable.
A26: Note | C26: The K54 sleeper leaves Shenyang North at 22:00, so a late awards ceremony on 15 Nov is fine. If it runs past ~21:15, take the Air China through ticket SHE 09:00 → UB 15:05 on 16 Nov ($286 pp) and sleep in Shenyang.
A27: Note | C27: Chinese train tickets open 15 days before travel (day of travel counts, e.g. 13 Nov trains on 30 Oct) on 12306 / Trip.com / Ctrip; passports needed to buy. Beijing → Nanjing sleepers (D5 21:21) leave too soon after MIAT lands at 19:30, so the 6 Nov Beijing night stays.
