Workbook

Sheet Compare
A1: ICPC single-contest trip plans — Shenyang, Shanghai, Nanchang, Hong Kong, EC Final Hangzhou
A2: Each trip planned as if it is the only contest attended. Two to three variants per contest. Two scenarios: the UNFUNDED regional (3 contestants pay everything) and the FUNDED regional (₮12M from the university, coach travels: 4 people). University funding covers flights, trains, hotels, meals & local transport; contest fees and 'Other' are personal. Prices: Trip.com / 12306 / ChinaTicketOnline / SlickTrip / Booking.com checked 30 Sep – 22 Oct 2026. Blue = inputs; yellow = key assumptions; green = links.
A4: Shared inputs
A5: University funding – funded regional (MNT) | B5: 12000000 | C5: One regional is funded with ₮12M and the coach travels (4 people: 3 contestants + coach); used in every "4 ppl" column
A6: Travelers – unfunded regional | B6: 3 | C6: 3 contestants, one room, everyone pays
A7: Travelers – funded regional (with coach) | B7: 4 | C7: 3 contestants + coach, two rooms (or one family room for 4)
A8: USD → MNT | B8: 3598 | C8: Mid-market, Xe/Investing.com, 29–30 Sep 2026
A9: CNY → MNT | B9: 536 | C9: Mid-market, Xe/currency.wiki, late Sep 2026
A10: HKD → MNT | B10: 461 | C10: Derived from USD rate and the HKD peg (~7.8 HKD per USD)
A11: Contingency % (on university-paid part) | B11: 0.1 | C11: Buffer for fare changes, FX spread, extras
A12: University funding – unfunded regional (MNT) | B12: 0 | C12: The other regional is unfunded: the 3 contestants pay everything themselves; used in every "3 ppl" column
A13: Side-by-side (all figures incl. 10% contingency on the travel + stay part). 3 ppl = the UNFUNDED regional, 4 ppl = the FUNDED regional (₮12M, coach travels)
A14: Plan | B14: Travel + stay total – 3 ppl (unfunded: paid by the contestants) | C14: Funding left – 3 ppl (funding ₮0) | D14: Cost per person – 3 ppl (everything incl. fee) | E14: Travel + stay total – 4 ppl (funded) | F14: Left of the ₮12M – 4 ppl (negative = over) | G14: Out-of-pocket per person – 4 ppl (fee, UB taxi, insurance, eSIM) | H14: Whole trip – 3 ppl | I14: Whole trip – 4 ppl | J14: Planes & trains | K14: Door-to-door | L14: Fits ₮12M incl. 10% contingency? | M14: Left of ₮12M before contingency (4 ppl)
A15: Shenyang – Budget | B15: ='Shenyang – Budget'!H34 | C15: ='Shenyang – Budget'!H35 | D15: ='Shenyang – Budget'!H37 | E15: ='Shenyang – Budget'!K34 | F15: ='Shenyang – Budget'!K35 | G15: ='Shenyang – Budget'!K37 | H15: ='Shenyang – Budget'!H38 | I15: ='Shenyang – Budget'!K38 | J15: ='Shenyang – Budget'!H39 | K15: ='Shenyang – Budget'!D69 | L15: =IF(F15>=0,"yes","over by "&TEXT(-F15,"#,##0")&" ₮") | M15: =Compare!$B$5-E15/(1+Compare!$B$11)
A16: Shenyang – Comfort | B16: ='Shenyang – Comfort'!H33 | C16: ='Shenyang – Comfort'!H34 | D16: ='Shenyang – Comfort'!H36 | E16: ='Shenyang – Comfort'!K33 | F16: ='Shenyang – Comfort'!K34 | G16: ='Shenyang – Comfort'!K36 | H16: ='Shenyang – Comfort'!H37 | I16: ='Shenyang – Comfort'!K37 | J16: ='Shenyang – Comfort'!H38 | K16: ='Shenyang – Comfort'!D68 | L16: =IF(F16>=0,"yes","over by "&TEXT(-F16,"#,##0")&" ₮") | M16: =Compare!$B$5-E16/(1+Compare!$B$11)
A17: Shenyang – Budget (G-train) | B17: ='Shenyang – Budget (G-train)'!H35 | C17: ='Shenyang – Budget (G-train)'!H36 | D17: ='Shenyang – Budget (G-train)'!H38 | E17: ='Shenyang – Budget (G-train)'!K35 | F17: ='Shenyang – Budget (G-train)'!K36 | G17: ='Shenyang – Budget (G-train)'!K38 | H17: ='Shenyang – Budget (G-train)'!H39 | I17: ='Shenyang – Budget (G-train)'!K39 | J17: ='Shenyang – Budget (G-train)'!H40 | K17: ='Shenyang – Budget (G-train)'!D70 | L17: =IF(F17>=0,"yes","over by "&TEXT(-F17,"#,##0")&" ₮") | M17: =Compare!$B$5-E17/(1+Compare!$B$11)
A18: Shenyang – Comfort (G-train) | B18: ='Shenyang – Comfort (G-train)'!H35 | C18: ='Shenyang – Comfort (G-train)'!H36 | D18: ='Shenyang – Comfort (G-train)'!H38 | E18: ='Shenyang – Comfort (G-train)'!K35 | F18: ='Shenyang – Comfort (G-train)'!K36 | G18: ='Shenyang – Comfort (G-train)'!K38 | H18: ='Shenyang – Comfort (G-train)'!H39 | I18: ='Shenyang – Comfort (G-train)'!K39 | J18: ='Shenyang – Comfort (G-train)'!H40 | K18: ='Shenyang – Comfort (G-train)'!D71 | L18: =IF(F18>=0,"yes","over by "&TEXT(-F18,"#,##0")&" ₮") | M18: =Compare!$B$5-E18/(1+Compare!$B$11)
A19: Shenyang – Sleep first | B19: ='Shenyang – Sleep first'!H34 | C19: ='Shenyang – Sleep first'!H35 | D19: ='Shenyang – Sleep first'!H37 | E19: ='Shenyang – Sleep first'!K34 | F19: ='Shenyang – Sleep first'!K35 | G19: ='Shenyang – Sleep first'!K37 | H19: ='Shenyang – Sleep first'!H38 | I19: ='Shenyang – Sleep first'!K38 | J19: ='Shenyang – Sleep first'!H39 | K19: ='Shenyang – Sleep first'!D70 | L19: =IF(F19>=0,"yes","over by "&TEXT(-F19,"#,##0")&" ₮") | M19: =Compare!$B$5-E19/(1+Compare!$B$11)
A20: Shenyang – Sleep value | B20: ='Shenyang – Sleep value'!H34 | C20: ='Shenyang – Sleep value'!H35 | D20: ='Shenyang – Sleep value'!H37 | E20: ='Shenyang – Sleep value'!K34 | F20: ='Shenyang – Sleep value'!K35 | G20: ='Shenyang – Sleep value'!K37 | H20: ='Shenyang – Sleep value'!H38 | I20: ='Shenyang – Sleep value'!K38 | J20: ='Shenyang – Sleep value'!H39 | K20: ='Shenyang – Sleep value'!D70 | L20: =IF(F20>=0,"yes","over by "&TEXT(-F20,"#,##0")&" ₮") | M20: =Compare!$B$5-E20/(1+Compare!$B$11)
A21: Shenyang – Overland home | B21: ='Shenyang – Overland home'!H36 | C21: ='Shenyang – Overland home'!H37 | D21: ='Shenyang – Overland home'!H39 | E21: ='Shenyang – Overland home'!K36 | F21: ='Shenyang – Overland home'!K37 | G21: ='Shenyang – Overland home'!K39 | H21: ='Shenyang – Overland home'!H40 | I21: ='Shenyang – Overland home'!K40 | J21: ='Shenyang – Overland home'!H41 | K21: ='Shenyang – Overland home'!D75 | L21: =IF(F21>=0,"yes","over by "&TEXT(-F21,"#,##0")&" ₮") | M21: =Compare!$B$5-E21/(1+Compare!$B$11)
A22: Shenyang – Overland out (seats) | B22: ='Shenyang – Overland out (seats)'!H36 | C22: ='Shenyang – Overland out (seats)'!H37 | D22: ='Shenyang – Overland out (seats)'!H39 | E22: ='Shenyang – Overland out (seats)'!K36 | F22: ='Shenyang – Overland out (seats)'!K37 | G22: ='Shenyang – Overland out (seats)'!K39 | H22: ='Shenyang – Overland out (seats)'!H40 | I22: ='Shenyang – Overland out (seats)'!K40 | J22: ='Shenyang – Overland out (seats)'!H41 | K22: ='Shenyang – Overland out (seats)'!D71 | L22: =IF(F22>=0,"yes","over by "&TEXT(-F22,"#,##0")&" ₮") | M22: =Compare!$B$5-E22/(1+Compare!$B$11)
A23: Shenyang – Overland out, berths | B23: ='Shenyang – Overland out, berths'!H36 | C23: ='Shenyang – Overland out, berths'!H37 | D23: ='Shenyang – Overland out, berths'!H39 | E23: ='Shenyang – Overland out, berths'!K36 | F23: ='Shenyang – Overland out, berths'!K37 | G23: ='Shenyang – Overland out, berths'!K39 | H23: ='Shenyang – Overland out, berths'!H40 | I23: ='Shenyang – Overland out, berths'!K40 | J23: ='Shenyang – Overland out, berths'!H41 | K23: ='Shenyang – Overland out, berths'!D71 | L23: =IF(F23>=0,"yes","over by "&TEXT(-F23,"#,##0")&" ₮") | M23: =Compare!$B$5-E23/(1+Compare!$B$11)
A24: Shenyang – Manzhouli seats | B24: ='Shenyang – Manzhouli seats'!H35 | C24: ='Shenyang – Manzhouli seats'!H36 | D24: ='Shenyang – Manzhouli seats'!H38 | E24: ='Shenyang – Manzhouli seats'!K35 | F24: ='Shenyang – Manzhouli seats'!K36 | G24: ='Shenyang – Manzhouli seats'!K38 | H24: ='Shenyang – Manzhouli seats'!H39 | I24: ='Shenyang – Manzhouli seats'!K39 | J24: ='Shenyang – Manzhouli seats'!H40 | K24: ='Shenyang – Manzhouli seats'!D72 | L24: =IF(F24>=0,"yes","over by "&TEXT(-F24,"#,##0")&" ₮") | M24: =Compare!$B$5-E24/(1+Compare!$B$11)
A25: Shenyang – Hunnu Daxing + K341 | B25: ='Shenyang – Hunnu Daxing + K341'!H34 | C25: ='Shenyang – Hunnu Daxing + K341'!H35 | D25: ='Shenyang – Hunnu Daxing + K341'!H37 | E25: ='Shenyang – Hunnu Daxing + K341'!K34 | F25: ='Shenyang – Hunnu Daxing + K341'!K35 | G25: ='Shenyang – Hunnu Daxing + K341'!K37 | H25: ='Shenyang – Hunnu Daxing + K341'!H38 | I25: ='Shenyang – Hunnu Daxing + K341'!K38 | J25: ='Shenyang – Hunnu Daxing + K341'!H39 | K25: ='Shenyang – Hunnu Daxing + K341'!D68 | L25: =IF(F25>=0,"yes","over by "&TEXT(-F25,"#,##0")&" ₮") | M25: =Compare!$B$5-E25/(1+Compare!$B$11)
A26: Shenyang – MIAT 13 Nov + K341 | B26: ='Shenyang – MIAT 13 Nov + K341'!H34 | C26: ='Shenyang – MIAT 13 Nov + K341'!H35 | D26: ='Shenyang – MIAT 13 Nov + K341'!H37 | E26: ='Shenyang – MIAT 13 Nov + K341'!K34 | F26: ='Shenyang – MIAT 13 Nov + K341'!K35 | G26: ='Shenyang – MIAT 13 Nov + K341'!K37 | H26: ='Shenyang – MIAT 13 Nov + K341'!H38 | I26: ='Shenyang – MIAT 13 Nov + K341'!K38 | J26: ='Shenyang – MIAT 13 Nov + K341'!H39 | K26: ='Shenyang – MIAT 13 Nov + K341'!D68 | L26: =IF(F26>=0,"yes","over by "&TEXT(-F26,"#,##0")&" ₮") | M26: =Compare!$B$5-E26/(1+Compare!$B$11)
A27: Shenyang – Hunnu Erenhot | B27: ='Shenyang – Hunnu Erenhot'!H35 | C27: ='Shenyang – Hunnu Erenhot'!H36 | D27: ='Shenyang – Hunnu Erenhot'!H38 | E27: ='Shenyang – Hunnu Erenhot'!K35 | F27: ='Shenyang – Hunnu Erenhot'!K36 | G27: ='Shenyang – Hunnu Erenhot'!K38 | H27: ='Shenyang – Hunnu Erenhot'!H39 | I27: ='Shenyang – Hunnu Erenhot'!K39 | J27: ='Shenyang – Hunnu Erenhot'!H40 | K27: ='Shenyang – Hunnu Erenhot'!D69 | L27: =IF(F27>=0,"yes","over by "&TEXT(-F27,"#,##0")&" ₮") | M27: =Compare!$B$5-E27/(1+Compare!$B$11)
A28: Shenyang – Hohhot red-eye | B28: ='Shenyang – Hohhot red-eye'!H35 | C28: ='Shenyang – Hohhot red-eye'!H36 | D28: ='Shenyang – Hohhot red-eye'!H38 | E28: ='Shenyang – Hohhot red-eye'!K35 | F28: ='Shenyang – Hohhot red-eye'!K36 | G28: ='Shenyang – Hohhot red-eye'!K38 | H28: ='Shenyang – Hohhot red-eye'!H39 | I28: ='Shenyang – Hohhot red-eye'!K39 | J28: ='Shenyang – Hohhot red-eye'!H40 | K28: ='Shenyang – Hohhot red-eye'!D72 | L28: =IF(F28>=0,"yes","over by "&TEXT(-F28,"#,##0")&" ₮") | M28: =Compare!$B$5-E28/(1+Compare!$B$11)
A29: Shenyang – Hohhot + Spring | B29: ='Shenyang – Hohhot + Spring'!H35 | C29: ='Shenyang – Hohhot + Spring'!H36 | D29: ='Shenyang – Hohhot + Spring'!H38 | E29: ='Shenyang – Hohhot + Spring'!K35 | F29: ='Shenyang – Hohhot + Spring'!K36 | G29: ='Shenyang – Hohhot + Spring'!K38 | H29: ='Shenyang – Hohhot + Spring'!H39 | I29: ='Shenyang – Hohhot + Spring'!K39 | J29: ='Shenyang – Hohhot + Spring'!H40 | K29: ='Shenyang – Hohhot + Spring'!D70 | L29: =IF(F29>=0,"yes","over by "&TEXT(-F29,"#,##0")&" ₮") | M29: =Compare!$B$5-E29/(1+Compare!$B$11)
A30: Shanghai – Sleeper | B30: ='Shanghai – Sleeper'!H35 | C30: ='Shanghai – Sleeper'!H36 | D30: ='Shanghai – Sleeper'!H38 | E30: ='Shanghai – Sleeper'!K35 | F30: ='Shanghai – Sleeper'!K36 | G30: ='Shanghai – Sleeper'!K38 | H30: ='Shanghai – Sleeper'!H39 | I30: ='Shanghai – Sleeper'!K39 | J30: ='Shanghai – Sleeper'!H40 | K30: ='Shanghai – Sleeper'!D71 | L30: =IF(F30>=0,"yes","over by "&TEXT(-F30,"#,##0")&" ₮") | M30: =Compare!$B$5-E30/(1+Compare!$B$11)
A31: Shanghai – Spring nonstop | B31: ='Shanghai – Spring nonstop'!H31 | C31: ='Shanghai – Spring nonstop'!H32 | D31: ='Shanghai – Spring nonstop'!H34 | E31: ='Shanghai – Spring nonstop'!K31 | F31: ='Shanghai – Spring nonstop'!K32 | G31: ='Shanghai – Spring nonstop'!K34 | H31: ='Shanghai – Spring nonstop'!H35 | I31: ='Shanghai – Spring nonstop'!K35 | J31: ='Shanghai – Spring nonstop'!H36 | K31: ='Shanghai – Spring nonstop'!D65 | L31: =IF(F31>=0,"yes","over by "&TEXT(-F31,"#,##0")&" ₮") | M31: =Compare!$B$5-E31/(1+Compare!$B$11)
A32: Shanghai – Nonstop cheap rooms | B32: ='Shanghai – Nonstop cheap rooms'!H31 | C32: ='Shanghai – Nonstop cheap rooms'!H32 | D32: ='Shanghai – Nonstop cheap rooms'!H34 | E32: ='Shanghai – Nonstop cheap rooms'!K31 | F32: ='Shanghai – Nonstop cheap rooms'!K32 | G32: ='Shanghai – Nonstop cheap rooms'!K34 | H32: ='Shanghai – Nonstop cheap rooms'!H35 | I32: ='Shanghai – Nonstop cheap rooms'!K35 | J32: ='Shanghai – Nonstop cheap rooms'!H36 | K32: ='Shanghai – Nonstop cheap rooms'!D65 | L32: =IF(F32>=0,"yes","over by "&TEXT(-F32,"#,##0")&" ₮") | M32: =Compare!$B$5-E32/(1+Compare!$B$11)
A33: Shanghai – Fly out, train home | B33: ='Shanghai – Fly out, train home'!H35 | C33: ='Shanghai – Fly out, train home'!H36 | D33: ='Shanghai – Fly out, train home'!H38 | E33: ='Shanghai – Fly out, train home'!K35 | F33: ='Shanghai – Fly out, train home'!K36 | G33: ='Shanghai – Fly out, train home'!K38 | H33: ='Shanghai – Fly out, train home'!H39 | I33: ='Shanghai – Fly out, train home'!K39 | J33: ='Shanghai – Fly out, train home'!H40 | K33: ='Shanghai – Fly out, train home'!D71 | L33: =IF(F33>=0,"yes","over by "&TEXT(-F33,"#,##0")&" ₮") | M33: =Compare!$B$5-E33/(1+Compare!$B$11)
A34: Shanghai – Train (no sleeper) | B34: ='Shanghai – Train (no sleeper)'!H37 | C34: ='Shanghai – Train (no sleeper)'!H38 | D34: ='Shanghai – Train (no sleeper)'!H40 | E34: ='Shanghai – Train (no sleeper)'!K37 | F34: ='Shanghai – Train (no sleeper)'!K38 | G34: ='Shanghai – Train (no sleeper)'!K40 | H34: ='Shanghai – Train (no sleeper)'!H41 | I34: ='Shanghai – Train (no sleeper)'!K41 | J34: ='Shanghai – Train (no sleeper)'!H42 | K34: ='Shanghai – Train (no sleeper)'!D74 | L34: =IF(F34>=0,"yes","over by "&TEXT(-F34,"#,##0")&" ₮") | M34: =Compare!$B$5-E34/(1+Compare!$B$11)
A35: Nanchang – Sleeper | B35: ='Nanchang – Sleeper'!H34 | C35: ='Nanchang – Sleeper'!H35 | D35: ='Nanchang – Sleeper'!H37 | E35: ='Nanchang – Sleeper'!K34 | F35: ='Nanchang – Sleeper'!K35 | G35: ='Nanchang – Sleeper'!K37 | H35: ='Nanchang – Sleeper'!H38 | I35: ='Nanchang – Sleeper'!K38 | J35: ='Nanchang – Sleeper'!H39 | K35: ='Nanchang – Sleeper'!D70 | L35: =IF(F35>=0,"yes","over by "&TEXT(-F35,"#,##0")&" ₮") | M35: =Compare!$B$5-E35/(1+Compare!$B$11)
A36: Nanchang – Comfort | B36: ='Nanchang – Comfort'!H36 | C36: ='Nanchang – Comfort'!H37 | D36: ='Nanchang – Comfort'!H39 | E36: ='Nanchang – Comfort'!K36 | F36: ='Nanchang – Comfort'!K37 | G36: ='Nanchang – Comfort'!K39 | H36: ='Nanchang – Comfort'!H40 | I36: ='Nanchang – Comfort'!K40 | J36: ='Nanchang – Comfort'!H41 | K36: ='Nanchang – Comfort'!D72 | L36: =IF(F36>=0,"yes","over by "&TEXT(-F36,"#,##0")&" ₮") | M36: =Compare!$B$5-E36/(1+Compare!$B$11)
A37: Nanchang – Fly in (Air China) | B37: ='Nanchang – Fly in (Air China)'!H34 | C37: ='Nanchang – Fly in (Air China)'!H35 | D37: ='Nanchang – Fly in (Air China)'!H37 | E37: ='Nanchang – Fly in (Air China)'!K34 | F37: ='Nanchang – Fly in (Air China)'!K35 | G37: ='Nanchang – Fly in (Air China)'!K37 | H37: ='Nanchang – Fly in (Air China)'!H38 | I37: ='Nanchang – Fly in (Air China)'!K38 | J37: ='Nanchang – Fly in (Air China)'!H39 | K37: ='Nanchang – Fly in (Air China)'!D68 | L37: =IF(F37>=0,"yes","over by "&TEXT(-F37,"#,##0")&" ₮") | M37: =Compare!$B$5-E37/(1+Compare!$B$11)
A38: Hong Kong – Budget | B38: ='Hong Kong – Budget'!H30 | C38: ='Hong Kong – Budget'!H31 | D38: ='Hong Kong – Budget'!H33 | E38: ='Hong Kong – Budget'!K30 | F38: ='Hong Kong – Budget'!K31 | G38: ='Hong Kong – Budget'!K33 | H38: ='Hong Kong – Budget'!H34 | I38: ='Hong Kong – Budget'!K34 | J38: ='Hong Kong – Budget'!H35 | K38: ='Hong Kong – Budget'!D60 | L38: =IF(F38>=0,"yes","over by "&TEXT(-F38,"#,##0")&" ₮") | M38: =Compare!$B$5-E38/(1+Compare!$B$11)
A39: Hong Kong – Comfort | B39: ='Hong Kong – Comfort'!H30 | C39: ='Hong Kong – Comfort'!H31 | D39: ='Hong Kong – Comfort'!H33 | E39: ='Hong Kong – Comfort'!K30 | F39: ='Hong Kong – Comfort'!K31 | G39: ='Hong Kong – Comfort'!K33 | H39: ='Hong Kong – Comfort'!H34 | I39: ='Hong Kong – Comfort'!K34 | J39: ='Hong Kong – Comfort'!H35 | K39: ='Hong Kong – Comfort'!D60 | L39: =IF(F39>=0,"yes","over by "&TEXT(-F39,"#,##0")&" ₮") | M39: =Compare!$B$5-E39/(1+Compare!$B$11)
A40: Hong Kong – Value | B40: ='Hong Kong – Value'!H30 | C40: ='Hong Kong – Value'!H31 | D40: ='Hong Kong – Value'!H33 | E40: ='Hong Kong – Value'!K30 | F40: ='Hong Kong – Value'!K31 | G40: ='Hong Kong – Value'!K33 | H40: ='Hong Kong – Value'!H34 | I40: ='Hong Kong – Value'!K34 | J40: ='Hong Kong – Value'!H35 | K40: ='Hong Kong – Value'!D60 | L40: =IF(F40>=0,"yes","over by "&TEXT(-F40,"#,##0")&" ₮") | M40: =Compare!$B$5-E40/(1+Compare!$B$11)
A41: Hong Kong – Sleep first | B41: ='Hong Kong – Sleep first'!H30 | C41: ='Hong Kong – Sleep first'!H31 | D41: ='Hong Kong – Sleep first'!H33 | E41: ='Hong Kong – Sleep first'!K30 | F41: ='Hong Kong – Sleep first'!K31 | G41: ='Hong Kong – Sleep first'!K33 | H41: ='Hong Kong – Sleep first'!H34 | I41: ='Hong Kong – Sleep first'!K34 | J41: ='Hong Kong – Sleep first'!H35 | K41: ='Hong Kong – Sleep first'!D60 | L41: =IF(F41>=0,"yes","over by "&TEXT(-F41,"#,##0")&" ₮") | M41: =Compare!$B$5-E41/(1+Compare!$B$11)
...

Sheet Sleep check
A1: Sleep check – protect the nights before the contest, spend nothing on comfort after it
A2: Rules used: (1) the two nights before the contest day are in a real bed, quiet, ≤30 min from the venue, ≥7.5 h in bed and no wake-up before ~06:00 on contest morning; (2) no overnight train or flight on the contest eve; a sleeper before day 1 only if it is a soft sleeper that arrives by midday and there is a bed night in between; (3) flights before 08:00 only ≥2 nights before the contest; (4) after the contest anything goes – hard sleepers, seats, red-eye trains, 04:30 airport runs – so the cheapest option is used. No time-zone effect: Mongolia, China and Hong Kong are all UTC+8.
A4: Plan | B4: Contest day / day 1 | C4: Night −3 | D4: Night −2 (before day 1) | E4: Night −1 (contest eve) | F4: Contest morning | G4: Verdict | H4: Sleep fix / what changed
A5: Shenyang – Comfort | B5: Sun 15 Nov / Sat 14 Nov | C5: 12 Nov RiCH hotel (after a 04:30 start for MIAT 07:30; nap in the afternoon) | D5: 13 Nov RiCH, free rest day | E5: 14 Nov RiCH, family room, quiet | F5: Walk 18 min, wake ~07:00 | G5: BEST | H5: Sleeper K54 is after the contest, so it is now a hard sleeper (soft was ¥263): saves ~₮0.16M (₮6.2M total).
A6: Shenyang – Budget | B6: Sun 15 Nov / Sat 14 Nov | C6: 12 Nov at home | D6: 13 Nov K53 soft sleeper 22:35–07:00 (was hard): ~5–6 h, then day-1 registration | E6: 14 Nov Bestay hotel (8.2, budget chain) | F6: Metro 25 min, wake ~06:30 | G6: WATCH | H6: K53 is the night before day 1, so it is now a soft sleeper (+¥92 pp, +₮0.16M; ₮5.2M total). Nap on arrival; the contest eve is in a bed. Safer: Comfort or either G-train variant.
A7: Shenyang – Comfort (G-train) | B7: Sun 15 Nov / Sat 14 Nov | C7: 12 Nov RiCH hotel | D7: 13 Nov RiCH | E7: 14 Nov RiCH | F7: Walk 18 min, wake ~07:00 | G7: BEST | H7: All beds before the contest; the Beijing hotel night (Dequan) is after it. +0.5M vs the sleeper plan.
A8: Shenyang – Budget (G-train) | B8: Sun 15 Nov / Sat 14 Nov | C8: 12 Nov at home | D8: 13 Nov Dequan hotel Beijing, wake 05:45 for G101 08:00 (~6.5 h) | E8: 14 Nov Bestay hotel | F8: Metro 25 min, wake ~06:30 | G8: OK | H8: Two nights in beds; one early wake two nights before the contest. Cheapest plan with no sleeper before the contest.
A9: Shenyang – Sleep first | B9: Sun 15 Nov / Sat 14 Nov | C9: 12 Nov NEU International (normal wake-up ~08:00 for Air China 11:50; bed ~23:00) | D9: 13 Nov same room, free rest day, no alarm | E9: 14 Nov same room, twin room, 580 m | F9: Walk 7 min, wake ~07:00 | G9: BEST | H9: No alarm before ~08:00 on any day before the contest (Air China 11:50 instead of MIAT 07:30, ¥195 ≈ ₮0.10M pp more on Ctrip), three nights in the same room and a bed each (2 twin rooms, 38 m², 9.7). After the contest the cheapest: K28 hard seat + Air China 12:55. ₮2.89M per person (3 ppl).
A10: Shenyang – Sleep value | B10: Sun 15 Nov / Sat 14 Nov | C10: 12 Nov Ji Hotel (normal wake-up ~08:00 for Air China 11:50; bed ~23:00) | D10: 13 Nov same room, free rest day, no alarm | E10: 14 Nov same room, twin room, ~15 min walk | F10: Walk ~15 min, wake ~06:50 | G10: BEST | H10: Same timing and a bed each (2 twin rooms, King Koil mattresses, 9.0); smaller rooms and a ~15 min walk. ₮2.69M per person – ₮0.20M less than Sleep first.
A11: Shenyang – Overland home | B11: Sun 15 Nov / Sat 14 Nov | C11: 12 Nov Ji Hotel (normal wake-up ~08:00 for Air China 11:50; bed ~23:00) | D11: 13 Nov same room, free rest day, no alarm | E11: 14 Nov same room, twin room, ~15 min walk | F11: Walk ~15 min, wake ~06:50 | G11: BEST | H11: Identical to Sleep value before the contest. After it: K1568 + 4652 hard sleepers, jeep across the border at Erenhot, UBTZ 275 platskart, home 18 Nov 09:20. ₮2.37M per person – the cheapest Shenyang plan without an early start or a sleeper before the contest.
A12: Shenyang – Overland out (seats) | B12: Sun 15 Nov / Sat 14 Nov | C12: 12 Nov UBTZ 276 seat | D12: 13 Nov T301 hard seat 19:30–10:16, then registration | E12: 14 Nov Ji Hotel, twin room | F12: Walk ~15 min, wake ~06:50 | G12: POOR | H12: Two seated train nights back to back before day 1. Leaving on 10 Nov instead adds two hotel nights (~₮0.16M pp) and turns this into OK. Berths: see 'Overland out, berths'.
A13: Shenyang – Overland out, berths | B13: Sun 15 Nov / Sat 14 Nov | C13: 12 Nov UBTZ 276 platskart berth | D13: 13 Nov T301 hard sleeper, then registration | E13: 14 Nov Ji Hotel, twin room | F13: Walk ~15 min, wake ~06:50 | G13: POOR | H13: Lying down both nights, but still two train nights in a row before day 1. +₮0.09M pp over seats.
A14: Shenyang – Manzhouli seats | B14: Sun 15 Nov / Sat 14 Nov | C14: 12 Nov Ji Hotel (after a night sitting up on K7092; arrive 14:32) | D14: 13 Nov Ji Hotel, free rest day | E14: 14 Nov Ji Hotel, twin room | F14: Walk ~15 min, wake ~06:50 | G14: OK | H14: The seated night is four nights before the contest and three hotel nights follow. Soft sleeper on K7092 (+¥205 pp) makes it BEST.
A15: Shenyang – Hunnu Daxing + K341 | B15: Sun 15 Nov / Sat 14 Nov | C15: 12 Nov at home | D15: 13 Nov K341 hard seat 23:00–08:47, then registration | E15: 14 Nov Ji Hotel, twin room | F15: Walk ~15 min, wake ~06:50 | G15: POOR | H15: Seated night right before day 1. K341 hard sleeper (+¥82 pp) or K53 22:35 soft sleeper (¥263) brings it to WATCH.
... A36: Nanjing + Shenyang (older workbook A / B) | B36: Nanjing Sun 8 Nov; Shenyang Sun 15 Nov | C36: 6 Nov Beijing hotel after MIAT lands 19:30, wake ~06:00 for the G-train | D36: 7 Nov Nanjing hotel (A 1 km, B 15 min metro) | E36: Shenyang: Z366 sleeper 12 Nov → hotels 13 and 14 Nov | F36: Nanjing walk / Shenyang walk | G36: OK | H36: K54 home after the Shenyang contest is now a hard sleeper (soft was ¥263). Plan C (home between) uses K53 soft sleeper on 13 Nov = night before day 1 (WATCH).
A37: One regional is funded with ₮12M (coach travels, 4 people); the other is unfunded (3 contestants pay). The funded trip has little headroom (Hong Kong does not fit), and the unfunded trip pays for every hotel night, so protect sleep with timing and location first: arrive a day early only where it is cheap (Shenyang, Nanchang), pick the hotel closest to the venue, and take the cheap-but-bad options only after the contest.
A38: Where the money goes (use the headroom on sleep)
A39: One regional is funded with ₮12M (coach travels, 4 people); the other is unfunded (3 contestants pay). The funded trip has little headroom (Hong Kong does not fit), and the unfunded trip pays for every hotel night, so protect sleep with timing and location first: arrive a day early only where it is cheap (Shenyang, Nanchang), pick the hotel closest to the venue, and take the cheap-but-bad options only after the contest.
A40: Pre-contest upgrades applied: Shenyang Budget K53 hard → soft; Hong Kong Sleep first (2 rooms near HKU). Post-contest downgrades applied: Shenyang K54 soft → hard, Shanghai D8 sleeper → seat, Nanchang D136 sleeper → seat.
A41: Cheapest post-contest options if you want to go further: Nanchang Z182 20:01 → 08:46 hard seat (¥173.5 vs ¥271); Shanghai G808 17:25 is too early after the awards, so the D8 seat stays.
A42: Contest-day wake-up rule of thumb: bed by 22:30–23:00, up by 06:00–06:30 for a 09:00 start; avoid alcohol and late team dinners; no phone-based all-nighters on day 1.

Sheet Shenyang – Budget
A1: Shenyang – Budget
A2: Overnight sleeper trains Beijing ⇄ Shenyang (no Beijing hotel nights), budget room, one night in Shenyang.
A4: Days in destination (meals & local transport) | B4: 3 | C4: Evening 13 Nov → midday 16 Nov
A5: Shared inputs are on the Compare sheet. Scroll down for the day-by-day plan and door-to-door travel times.
A7: Category | B7: Item | C7: Date | D7: Travel time | E7: Unit cost (3 ppl) | F7: Currency | G7: Qty (3 ppl) | H7: Total MNT – 3 people | I7: Unit cost (4 ppl) | J7: Qty (4 ppl) | K7: Total MNT – 4 people | L7: Source / notes
A8: PAID BY UNIVERSITY
A9: Flights
B10: MIAT OM223 Ulaanbaatar → Beijing (PEK), 17:15–19:30 | C10: 13 Nov | D10: 0.09375 | E10: 150 | F10: USD | G10: =Compare!$B$6 | H10: =E10*G10*IF(F10="USD",Compare!$B$8,IF(F10="CNY",Compare!$B$9,IF(F10="HKD",Compare!$B$10,1))) | I10: =E10 | J10: =Compare!$B$7 | K10: =I10*J10*IF(F10="USD",Compare!$B$8,IF(F10="CNY",Compare!$B$9,IF(F10="HKD",Compare!$B$10,1))) | L10: Trip.com 1 Oct: MIAT 17:15–19:30 $150 pp (SlickTrip 30 Sep: $154)
B11: Air China Beijing (PEK) → Ulaanbaatar, nonstop 12:55–15:05 | C11: 16 Nov | D11: 0.090277778 | E11: 171 | F11: USD | G11: =Compare!$B$6 | H11: =E11*G11*IF(F11="USD",Compare!$B$8,IF(F11="CNY",Compare!$B$9,IF(F11="HKD",Compare!$B$10,1))) | I11: =E11 | J11: =Compare!$B$7 | K11: =I11*J11*IF(F11="USD",Compare!$B$8,IF(F11="CNY",Compare!$B$9,IF(F11="HKD",Compare!$B$10,1))) | L11: Trip.com 30 Sep: Air China nonstop $171 pp (MIAT OM224 11:30 was $194 on Trip.com, $196.33 on SlickTrip)
A12: Trains
B13: Overnight train K53 Beijing 22:35 → Shenyang North 07:00, soft sleeper (4-berth cabin; night before day 1) | C13: 13 Nov (night) | D13: 0.35069444 | E13: 263 | F13: CNY | G13: =Compare!$B$6 | H13: =E13*G13*IF(F13="USD",Compare!$B$8,IF(F13="CNY",Compare!$B$9,IF(F13="HKD",Compare!$B$10,1))) | I13: =E13 | J13: =Compare!$B$7 | K13: =I13*J13*IF(F13="USD",Compare!$B$8,IF(F13="CNY",Compare!$B$9,IF(F13="HKD",Compare!$B$10,1))) | L13: Ctrip 1 Oct / 12306 3 Oct: K53 soft sleeper ¥263 (hard ¥171). Soft on purpose: it is the night before the day-1 warm-up, so sleep matters. Replaces the Beijing night + morning G-train (¥339). MIAT lands 19:30, so ~1 h 20 min spare; if MIAT is late, use the one free change to a 14 Nov G-train. Sales open 30 Oct 10:00.
B14: Overnight train K54 Shenyang North 22:00 → Beijing 06:58, hard sleeper | C14: 15 Nov (night) | D14: 0.37361111 | E14: 171 | F14: CNY | G14: =Compare!$B$6 | H14: =E14*G14*IF(F14="USD",Compare!$B$8,IF(F14="CNY",Compare!$B$9,IF(F14="HKD",Compare!$B$10,1))) | I14: =E14 | J14: =Compare!$B$7 | K14: =I14*J14*IF(F14="USD",Compare!$B$8,IF(F14="CNY",Compare!$B$9,IF(F14="HKD",Compare!$B$10,1))) | L14: Ctrip 1 Oct: K54 hard sleeper ¥171, soft sleeper ¥263 (4-berth cabin). Leaves 22:00, so a late closing ceremony is fine; replaces the evening G-train (¥339) + a Beijing hotel night. Air China through ticket SHE 09:00 → UB 15:05 ($286) is the fallback. 12306 3 Oct: same official fares; sales open 1 Nov 09:00 (Shenyang North).
A15: Accommodation
B17: Bestay Hotel Express Shenyang (Huaiyuanmen; ~25 min metro to NEU Nanhu) | C17: 14 Nov (1 night) | E17: 86 | F17: CNY | G17: 1 | H17: =E17*G17*IF(F17="USD",Compare!$B$8,IF(F17="CNY",Compare!$B$9,IF(F17="HKD",Compare!$B$10,1))) | I17: 134 | J17: 1 | K17: =I17*J17*IF(F17="USD",Compare!$B$8,IF(F17="CNY",Compare!$B$9,IF(F17="HKD",Compare!$B$10,1))) | L17: Booking.com: 86/night (3 ppl, 1 room); 134 CNY for 2 rooms on 14 Nov.. Trip.com 1 Oct: rated 8.2 from 1,062 reviews (¥284 for 2 rooms × 2 nights) – the low price is real. Arrive 07:00 off the sleeper: leave bags until check-in
A19: Meals & local transport
B20: Meals | C20: in destination | E20: 80 | F20: CNY | G20: =Compare!$B$6*$B$4 | H20: =E20*G20*IF(F20="USD",Compare!$B$8,IF(F20="CNY",Compare!$B$9,IF(F20="HKD",Compare!$B$10,1))) | I20: =E20 | J20: =Compare!$B$7*$B$4 | K20: =I20*J20*IF(F20="USD",Compare!$B$8,IF(F20="CNY",Compare!$B$9,IF(F20="HKD",Compare!$B$10,1))) | L20: ASSUMPTION 80 CNY/person/day; hosts usually provide some meals on contest days
B21: Local transport (metro, taxis) | C21: in destination | E21: 30 | F21: CNY | G21: =Compare!$B$6*$B$4 | H21: =E21*G21*IF(F21="USD",Compare!$B$8,IF(F21="CNY",Compare!$B$9,IF(F21="HKD",Compare!$B$10,1))) | I21: =E21 | J21: =Compare!$B$7*$B$4 | K21: =I21*J21*IF(F21="USD",Compare!$B$8,IF(F21="CNY",Compare!$B$9,IF(F21="HKD",Compare!$B$10,1))) | L21: ASSUMPTION 30 CNY/person/day
A22: PAID PERSONALLY (university won't cover)
A23: Contest fee
B24: Shenyang regional registration fee (per team) | C24: pay by mid-Oct | E24: 1500 | F24: CNY | G24: 1 | H24: =E24*G24*IF(F24="USD",Compare!$B$8,IF(F24="CNY",Compare!$B$9,IF(F24="HKD",Compare!$B$10,1))) | I24: =E24 | J24: 1 | K24: =I24*J24*IF(F24="USD",Compare!$B$8,IF(F24="CNY",Compare!$B$9,IF(F24="HKD",Compare!$B$10,1))) | L24: ASSUMPTION: 1,500 CNY/team like recent EC regionals; 2026 Shenyang invitation not yet out
A25: Other
B26: Taxi to/from Chinggis Khaan airport (UB), per trip | C26: out & back | D26: 0.041666667 | E26: 100000 | F26: MNT | G26: 2 | H26: =E26*G26*IF(F26="USD",Compare!$B$8,IF(F26="CNY",Compare!$B$9,IF(F26="HKD",Compare!$B$10,1))) | I26: =E26 | J26: 2 | K26: =I26*J26*IF(F26="USD",Compare!$B$8,IF(F26="CNY",Compare!$B$9,IF(F26="HKD",Compare!$B$10,1))) | L26: ASSUMPTION 100k MNT per trip for the group
B27: Travel medical insurance | E27: 30000 | F27: MNT | G27: =Compare!$B$6 | H27: =E27*G27*IF(F27="USD",Compare!$B$8,IF(F27="CNY",Compare!$B$9,IF(F27="HKD",Compare!$B$10,1))) | I27: =E27 | J27: =Compare!$B$7 | K27: =I27*J27*IF(F27="USD",Compare!$B$8,IF(F27="CNY",Compare!$B$9,IF(F27="HKD",Compare!$B$10,1))) | L27: ASSUMPTION ~30k MNT per person, Mongolian insurer
B28: Mobile data eSIM | E28: 10 | F28: USD | G28: =Compare!$B$6 | H28: =E28*G28*IF(F28="USD",Compare!$B$8,IF(F28="CNY",Compare!$B$9,IF(F28="HKD",Compare!$B$10,1))) | I28: =E28 | J28: =Compare!$B$7 | K28: =I28*J28*IF(F28="USD",Compare!$B$8,IF(F28="CNY",Compare!$B$9,IF(F28="HKD",Compare!$B$10,1))) | L28: ASSUMPTION ~$10 pp
B29: Visa | E29: 0 | F29: MNT | G29: =Compare!$B$6 | H29: =E29*G29*IF(F29="USD",Compare!$B$8,IF(F29="CNY",Compare!$B$9,IF(F29="HKD",Compare!$B$10,1))) | I29: =E29 | J29: =Compare!$B$7 | K29: =I29*J29*IF(F29="USD",Compare!$B$8,IF(F29="CNY",Compare!$B$9,IF(F29="HKD",Compare!$B$10,1))) | L29: Mongolian passports: visa-free (mainland China up to 30 days; Hong Kong up to 14 days)
H31: 3 people – UNFUNDED | K31: 4 people – FUNDED ₮12M
G32: University-paid subtotal | H32: =SUM(H9:H21) | K32: =SUM(K9:K21)
G33: Contingency | H33: =H32*Compare!$B$11 | K33: =K32*Compare!$B$11
G34: University-paid total incl. contingency | H34: =H32+H33 | K34: =K32+K33
G35: Funding left (negative = over) | H35: =Compare!$B$12-H34 | K35: =Compare!$B$5-K34
G36: Personal costs – team | H36: =SUM(H23:H29) | K36: =SUM(K23:K29)
G37: Out-of-pocket per person (personal + any overrun) | H37: =(H36+MAX(0,-H35))/Compare!$B$6 | K37: =(K36+MAX(0,-K35))/Compare!$B$7
G38: Whole trip cost (university + personal) | H38: =H34+H36 | K38: =K34+K36
G39: Time in planes & trains | H39: =SUM(D10:D11)+SUM(D13:D14) | K39: =SUM(D10:D11)+SUM(D13:D14)
A41: Key facts
A42: Contest | B42: Asia Shenyang Regional, 14–15 Nov 2026 (provisional), Northeastern University – 2025 edition was on the Nanhu campus.
A43: Why this route | B43: Cheapest way from UB: MIAT to Beijing ($150) + overnight sleeper trains (¥171 each way, no Beijing hotel), Air China home ($171). Flying UB→Shenyang direct means an overnight in Seoul (~$514 pp one way) or a 1-stop via Beijing/Hohhot ($219–233, 8–15 h).
A44: Trade-off | B44: Two nights on sleeper trains (6-berth hard sleeper); very basic room; ~25 min metro to the venue.
A46: Day-by-day plan
A47: Date | B47: Sleep in | C47: What happens
...

Sheet Shenyang – Comfort
A1: Shenyang – Comfort
A2: Arrive a day early for rest, family room near the venue, MIAT + fast train out, overnight soft sleeper back to Beijing.
A4: Days in destination (meals & local transport) | B4: 4.5 | C4: 12 Nov morning → midday 16 Nov
A5: Shared inputs are on the Compare sheet. Scroll down for the day-by-day plan and door-to-door travel times.
A7: Category | B7: Item | C7: Date | D7: Travel time | E7: Unit cost (3 ppl) | F7: Currency | G7: Qty (3 ppl) | H7: Total MNT – 3 people | I7: Unit cost (4 ppl) | J7: Qty (4 ppl) | K7: Total MNT – 4 people | L7: Source / notes
A8: PAID BY UNIVERSITY
A9: Flights
B10: MIAT OM223 Ulaanbaatar → Beijing (PEK), 07:30–09:45 | C10: 12 Nov | D10: 0.09375 | E10: 151 | F10: USD | G10: =Compare!$B$6 | H10: =E10*G10*IF(F10="USD",Compare!$B$8,IF(F10="CNY",Compare!$B$9,IF(F10="HKD",Compare!$B$10,1))) | I10: =E10 | J10: =Compare!$B$7 | K10: =I10*J10*IF(F10="USD",Compare!$B$8,IF(F10="CNY",Compare!$B$9,IF(F10="HKD",Compare!$B$10,1))) | L10: Trip.com 30 Sep: MIAT 07:30–09:45 $151 pp (SlickTrip 30 Sep: $154)
B11: Air China Beijing (PEK) → Ulaanbaatar, nonstop 12:55–15:05 | C11: 16 Nov | D11: 0.090277778 | E11: 171 | F11: USD | G11: =Compare!$B$6 | H11: =E11*G11*IF(F11="USD",Compare!$B$8,IF(F11="CNY",Compare!$B$9,IF(F11="HKD",Compare!$B$10,1))) | I11: =E11 | J11: =Compare!$B$7 | K11: =I11*J11*IF(F11="USD",Compare!$B$8,IF(F11="CNY",Compare!$B$9,IF(F11="HKD",Compare!$B$10,1))) | L11: Trip.com 30 Sep: Air China nonstop $171 pp (MIAT OM224 11:30 was $194 on Trip.com, $196.33 on SlickTrip)
A12: Trains
B13: High-speed rail Beijing Chaoyang → Shenyang North, 2nd class | C13: 12 Nov (midday) | D13: 0.11388889 | E13: 339 | F13: CNY | G13: =Compare!$B$6 | H13: =E13*G13*IF(F13="USD",Compare!$B$8,IF(F13="CNY",Compare!$B$9,IF(F13="HKD",Compare!$B$10,1))) | I13: =E13 | J13: =Compare!$B$7 | K13: =I13*J13*IF(F13="USD",Compare!$B$8,IF(F13="CNY",Compare!$B$9,IF(F13="HKD",Compare!$B$10,1))) | L13: 12306: 339 CNY; fastest 2 h 44 min
B14: Overnight train K54 Shenyang North 22:00 → Beijing 06:58, hard sleeper (after the contest) | C14: 15 Nov (night) | D14: 0.37361111 | E14: 171 | F14: CNY | G14: =Compare!$B$6 | H14: =E14*G14*IF(F14="USD",Compare!$B$8,IF(F14="CNY",Compare!$B$9,IF(F14="HKD",Compare!$B$10,1))) | I14: =E14 | J14: =Compare!$B$7 | K14: =I14*J14*IF(F14="USD",Compare!$B$8,IF(F14="CNY",Compare!$B$9,IF(F14="HKD",Compare!$B$10,1))) | L14: Ctrip 1 Oct / 12306 3 Oct: K54 hard sleeper ¥171 (soft ¥263). Hard on purpose: it is after the contest, so sleep no longer matters (saves ¥92 pp). Leaves 22:00, so a late closing ceremony is fine; replaces the evening G-train (¥339) + a Beijing hotel night. Air China through ticket SHE 09:00 → UB 15:05 ($286) is the fallback. Sales open 1 Nov 09:00.
A15: Accommodation
B16: Shenyang RiCH Hotel, Sanhao St (~1.3 km to NEU Nanhu; Family Room sleeps 4, so one room for 3 or 4 ppl) | C16: 12–15 Nov (3 nights) | E16: 325.33 | F16: CNY | G16: 3 | H16: =E16*G16*IF(F16="USD",Compare!$B$8,IF(F16="CNY",Compare!$B$9,IF(F16="HKD",Compare!$B$10,1))) | I16: 325.33 | J16: 3 | K16: =I16*J16*IF(F16="USD",Compare!$B$8,IF(F16="CNY",Compare!$B$9,IF(F16="HKD",Compare!$B$10,1))) | L16: Trip.com 1 Oct: Family Room ¥976 for 3 nights, same price for 3 or 4 adults; rated 9.6 (1,802 reviews). Was Atour ¥527/night (3 ppl) / Mehood Lestie ¥718 (4 ppl, 2 rooms) on Booking.com
A18: Meals & local transport
B19: Meals | C19: in destination | E19: 80 | F19: CNY | G19: =Compare!$B$6*$B$4 | H19: =E19*G19*IF(F19="USD",Compare!$B$8,IF(F19="CNY",Compare!$B$9,IF(F19="HKD",Compare!$B$10,1))) | I19: =E19 | J19: =Compare!$B$7*$B$4 | K19: =I19*J19*IF(F19="USD",Compare!$B$8,IF(F19="CNY",Compare!$B$9,IF(F19="HKD",Compare!$B$10,1))) | L19: ASSUMPTION 80 CNY/person/day; hosts usually provide some meals on contest days
B20: Local transport (metro, taxis) | C20: in destination | E20: 30 | F20: CNY | G20: =Compare!$B$6*$B$4 | H20: =E20*G20*IF(F20="USD",Compare!$B$8,IF(F20="CNY",Compare!$B$9,IF(F20="HKD",Compare!$B$10,1))) | I20: =E20 | J20: =Compare!$B$7*$B$4 | K20: =I20*J20*IF(F20="USD",Compare!$B$8,IF(F20="CNY",Compare!$B$9,IF(F20="HKD",Compare!$B$10,1))) | L20: ASSUMPTION 30 CNY/person/day
A21: PAID PERSONALLY (university won't cover)
A22: Contest fee
B23: Shenyang regional registration fee (per team) | C23: pay by mid-Oct | E23: 1500 | F23: CNY | G23: 1 | H23: =E23*G23*IF(F23="USD",Compare!$B$8,IF(F23="CNY",Compare!$B$9,IF(F23="HKD",Compare!$B$10,1))) | I23: =E23 | J23: 1 | K23: =I23*J23*IF(F23="USD",Compare!$B$8,IF(F23="CNY",Compare!$B$9,IF(F23="HKD",Compare!$B$10,1))) | L23: ASSUMPTION: 1,500 CNY/team like recent EC regionals; 2026 Shenyang invitation not yet out
A24: Other
B25: Taxi to/from Chinggis Khaan airport (UB), per trip | C25: out & back | D25: 0.041666667 | E25: 100000 | F25: MNT | G25: 2 | H25: =E25*G25*IF(F25="USD",Compare!$B$8,IF(F25="CNY",Compare!$B$9,IF(F25="HKD",Compare!$B$10,1))) | I25: =E25 | J25: 2 | K25: =I25*J25*IF(F25="USD",Compare!$B$8,IF(F25="CNY",Compare!$B$9,IF(F25="HKD",Compare!$B$10,1))) | L25: ASSUMPTION 100k MNT per trip for the group
B26: Travel medical insurance | E26: 30000 | F26: MNT | G26: =Compare!$B$6 | H26: =E26*G26*IF(F26="USD",Compare!$B$8,IF(F26="CNY",Compare!$B$9,IF(F26="HKD",Compare!$B$10,1))) | I26: =E26 | J26: =Compare!$B$7 | K26: =I26*J26*IF(F26="USD",Compare!$B$8,IF(F26="CNY",Compare!$B$9,IF(F26="HKD",Compare!$B$10,1))) | L26: ASSUMPTION ~30k MNT per person, Mongolian insurer
B27: Mobile data eSIM | E27: 10 | F27: USD | G27: =Compare!$B$6 | H27: =E27*G27*IF(F27="USD",Compare!$B$8,IF(F27="CNY",Compare!$B$9,IF(F27="HKD",Compare!$B$10,1))) | I27: =E27 | J27: =Compare!$B$7 | K27: =I27*J27*IF(F27="USD",Compare!$B$8,IF(F27="CNY",Compare!$B$9,IF(F27="HKD",Compare!$B$10,1))) | L27: ASSUMPTION ~$10 pp
B28: Visa | E28: 0 | F28: MNT | G28: =Compare!$B$6 | H28: =E28*G28*IF(F28="USD",Compare!$B$8,IF(F28="CNY",Compare!$B$9,IF(F28="HKD",Compare!$B$10,1))) | I28: =E28 | J28: =Compare!$B$7 | K28: =I28*J28*IF(F28="USD",Compare!$B$8,IF(F28="CNY",Compare!$B$9,IF(F28="HKD",Compare!$B$10,1))) | L28: Mongolian passports: visa-free (mainland China up to 30 days; Hong Kong up to 14 days)
H30: 3 people – UNFUNDED | K30: 4 people – FUNDED ₮12M
G31: University-paid subtotal | H31: =SUM(H9:H20) | K31: =SUM(K9:K20)
G32: Contingency | H32: =H31*Compare!$B$11 | K32: =K31*Compare!$B$11
G33: University-paid total incl. contingency | H33: =H31+H32 | K33: =K31+K32
G34: Funding left (negative = over) | H34: =Compare!$B$12-H33 | K34: =Compare!$B$5-K33
G35: Personal costs – team | H35: =SUM(H22:H28) | K35: =SUM(K22:K28)
G36: Out-of-pocket per person (personal + any overrun) | H36: =(H35+MAX(0,-H34))/Compare!$B$6 | K36: =(K35+MAX(0,-K34))/Compare!$B$7
G37: Whole trip cost (university + personal) | H37: =H33+H35 | K37: =K33+K35
G38: Time in planes & trains | H38: =SUM(D10:D11)+SUM(D13:D14) | K38: =SUM(D10:D11)+SUM(D13:D14)
A40: Key facts
A41: Contest | B41: Asia Shenyang Regional, 14–15 Nov 2026 (provisional), Northeastern University Nanhu campus (2025 venue).
A42: Why this plan | B42: A full rest day before registration, hotel close to the venue, same cheap MIAT + rail route.
A43: Trade-off | B43: Two extra hotel nights and meals; very early flight from UB on 12 Nov; one night on the train back.
A45: Day-by-day plan
A46: Date | B46: Sleep in | C46: What happens
...

Sheet Shenyang – Budget (G-train)
A1: Shenyang – Budget (G-train)
A2: No sleeper trains: MIAT in the evening, Beijing hotel night, morning G-train, cheap budget hotel, evening G-train back and another Beijing night.
A4: Days in destination (meals & local transport) | B4: 3 | C4: Evening 13 Nov → midday 16 Nov
A5: Shared inputs are on the Compare sheet. Scroll down for the day-by-day plan and door-to-door travel times.
A7: Category | B7: Item | C7: Date | D7: Travel time | E7: Unit cost (3 ppl) | F7: Currency | G7: Qty (3 ppl) | H7: Total MNT – 3 people | I7: Unit cost (4 ppl) | J7: Qty (4 ppl) | K7: Total MNT – 4 people | L7: Source / notes
A8: PAID BY UNIVERSITY
A9: Flights
B10: MIAT OM223 Ulaanbaatar → Beijing (PEK), 17:15–19:30 | C10: 13 Nov | D10: 0.09375 | E10: 150 | F10: USD | G10: =Compare!$B$6 | H10: =E10*G10*IF(F10="USD",Compare!$B$8,IF(F10="CNY",Compare!$B$9,IF(F10="HKD",Compare!$B$10,1))) | I10: =E10 | J10: =Compare!$B$7 | K10: =I10*J10*IF(F10="USD",Compare!$B$8,IF(F10="CNY",Compare!$B$9,IF(F10="HKD",Compare!$B$10,1))) | L10: Trip.com 1 Oct: MIAT 17:15–19:30 $150 pp (SlickTrip 30 Sep: $154)
B11: Air China Beijing (PEK) → Ulaanbaatar, nonstop 12:55–15:05 | C11: 16 Nov | D11: 0.090277778 | E11: 171 | F11: USD | G11: =Compare!$B$6 | H11: =E11*G11*IF(F11="USD",Compare!$B$8,IF(F11="CNY",Compare!$B$9,IF(F11="HKD",Compare!$B$10,1))) | I11: =E11 | J11: =Compare!$B$7 | K11: =I11*J11*IF(F11="USD",Compare!$B$8,IF(F11="CNY",Compare!$B$9,IF(F11="HKD",Compare!$B$10,1))) | L11: Trip.com 30 Sep: Air China nonstop $171 pp (MIAT OM224 11:30 was $194 on Trip.com, $196.33 on SlickTrip)
A12: Trains
B13: High-speed rail Beijing Chaoyang 08:00 → Shenyang North 10:29 (G101), 2nd class | C13: 14 Nov (morning) | D13: 0.10347222 | E13: 355 | F13: CNY | G13: =Compare!$B$6 | H13: =E13*G13*IF(F13="USD",Compare!$B$8,IF(F13="CNY",Compare!$B$9,IF(F13="HKD",Compare!$B$10,1))) | I13: =E13 | J13: =Compare!$B$7 | K13: =I13*J13*IF(F13="USD",Compare!$B$8,IF(F13="CNY",Compare!$B$9,IF(F13="HKD",Compare!$B$10,1))) | L13: 12306 (queried 10 Oct for 20 Oct; fares fixed): G101 / G103 08:05 / G105 08:55 ¥355; slower G3503 08:25 → 11:56 ¥296
B14: High-speed rail Shenyang North 19:51 → Beijing Chaoyang 22:30 (G142), 2nd class | C14: 15 Nov (evening) | D14: 0.11041667 | E14: 268 | F14: CNY | G14: =Compare!$B$6 | H14: =E14*G14*IF(F14="USD",Compare!$B$8,IF(F14="CNY",Compare!$B$9,IF(F14="HKD",Compare!$B$10,1))) | I14: =E14 | J14: =Compare!$B$7 | K14: =I14*J14*IF(F14="USD",Compare!$B$8,IF(F14="CNY",Compare!$B$9,IF(F14="HKD",Compare!$B$10,1))) | L14: 12306 (queried 10 Oct for 20 Oct; fares fixed): G142 / G156 (Shenyang stn 19:05) / G3522 19:21 → 22:36 ¥268; G122 / G126 ¥344. Awards end ~17:00, so 19:51 leaves a safe margin
A15: Accommodation
B16: Dequan Railway Station Hotel, Beijing (~1 km from Beijing Chaoyang station; 3 ppl 1 room; 4 ppl 2 rooms) | C16: 13 & 15 Nov (2 nights) | E16: 304 | F16: CNY | G16: 2 | H16: =E16*G16*IF(F16="USD",Compare!$B$8,IF(F16="CNY",Compare!$B$9,IF(F16="HKD",Compare!$B$10,1))) | I16: 608 | J16: 2 | K16: =I16*J16*IF(F16="USD",Compare!$B$8,IF(F16="CNY",Compare!$B$9,IF(F16="HKD",Compare!$B$10,1))) | L16: Booking.com 9 Oct: ¥304 for 3 adults, 1 room per night; rated 8.7 (65 reviews). 4 ppl: ASSUMPTION 2 × ¥304 (rooms not searched)
B17: Bestay Hotel Express Shenyang (Huaiyuanmen; ~25 min metro to NEU Nanhu) | C17: 14 Nov (1 night) | E17: 86 | F17: CNY | G17: 1 | H17: =E17*G17*IF(F17="USD",Compare!$B$8,IF(F17="CNY",Compare!$B$9,IF(F17="HKD",Compare!$B$10,1))) | I17: 134 | J17: 1 | K17: =I17*J17*IF(F17="USD",Compare!$B$8,IF(F17="CNY",Compare!$B$9,IF(F17="HKD",Compare!$B$10,1))) | L17: Booking.com: 86/night (3 ppl, 1 room); 134 CNY for 2 rooms on 14 Nov. Trip.com 1 Oct confirms the price (rated 8.2, 1,062 reviews)
A18: Meals & local transport
B19: Meals | C19: in destination | E19: 80 | F19: CNY | G19: =Compare!$B$6*$B$4 | H19: =E19*G19*IF(F19="USD",Compare!$B$8,IF(F19="CNY",Compare!$B$9,IF(F19="HKD",Compare!$B$10,1))) | I19: =E19 | J19: =Compare!$B$7*$B$4 | K19: =I19*J19*IF(F19="USD",Compare!$B$8,IF(F19="CNY",Compare!$B$9,IF(F19="HKD",Compare!$B$10,1))) | L19: ASSUMPTION 80 CNY/person/day; hosts usually provide some meals on contest days
B20: Local transport (metro, taxis) | C20: in destination | E20: 30 | F20: CNY | G20: =Compare!$B$6*$B$4 | H20: =E20*G20*IF(F20="USD",Compare!$B$8,IF(F20="CNY",Compare!$B$9,IF(F20="HKD",Compare!$B$10,1))) | I20: =E20 | J20: =Compare!$B$7*$B$4 | K20: =I20*J20*IF(F20="USD",Compare!$B$8,IF(F20="CNY",Compare!$B$9,IF(F20="HKD",Compare!$B$10,1))) | L20: ASSUMPTION 30 CNY/person/day
B21: Taxi PEK → Beijing Chaoyang area (Dequan hotel) | C21: 13 Nov | E21: 120 | F21: CNY | G21: 1 | H21: =E21*G21*IF(F21="USD",Compare!$B$8,IF(F21="CNY",Compare!$B$9,IF(F21="HKD",Compare!$B$10,1))) | I21: =E21 | J21: 1 | K21: =I21*J21*IF(F21="USD",Compare!$B$8,IF(F21="CNY",Compare!$B$9,IF(F21="HKD",Compare!$B$10,1))) | L21: ASSUMPTION ~120 CNY per car, ~35 km at night (4 ppl may need an XL car)
B22: Taxi Dequan hotel → PEK | C22: 16 Nov | E22: 120 | F22: CNY | G22: 1 | H22: =E22*G22*IF(F22="USD",Compare!$B$8,IF(F22="CNY",Compare!$B$9,IF(F22="HKD",Compare!$B$10,1))) | I22: =E22 | J22: 1 | K22: =I22*J22*IF(F22="USD",Compare!$B$8,IF(F22="CNY",Compare!$B$9,IF(F22="HKD",Compare!$B$10,1))) | L22: ASSUMPTION ~120 CNY per car, ~35 km, leave ~09:00
A23: PAID PERSONALLY (university won't cover)
A24: Contest fee
B25: Shenyang regional registration fee (per team) | C25: pay by mid-Oct | E25: 1500 | F25: CNY | G25: 1 | H25: =E25*G25*IF(F25="USD",Compare!$B$8,IF(F25="CNY",Compare!$B$9,IF(F25="HKD",Compare!$B$10,1))) | I25: =E25 | J25: 1 | K25: =I25*J25*IF(F25="USD",Compare!$B$8,IF(F25="CNY",Compare!$B$9,IF(F25="HKD",Compare!$B$10,1))) | L25: ASSUMPTION: 1,500 CNY/team like recent EC regionals; 2026 Shenyang invitation not seen
A26: Other
B27: Taxi to/from Chinggis Khaan airport (UB), per trip | C27: out & back | D27: 0.041666667 | E27: 100000 | F27: MNT | G27: 2 | H27: =E27*G27*IF(F27="USD",Compare!$B$8,IF(F27="CNY",Compare!$B$9,IF(F27="HKD",Compare!$B$10,1))) | I27: =E27 | J27: 2 | K27: =I27*J27*IF(F27="USD",Compare!$B$8,IF(F27="CNY",Compare!$B$9,IF(F27="HKD",Compare!$B$10,1))) | L27: ASSUMPTION 100k MNT per trip for the group
B28: Travel medical insurance | E28: 30000 | F28: MNT | G28: =Compare!$B$6 | H28: =E28*G28*IF(F28="USD",Compare!$B$8,IF(F28="CNY",Compare!$B$9,IF(F28="HKD",Compare!$B$10,1))) | I28: =E28 | J28: =Compare!$B$7 | K28: =I28*J28*IF(F28="USD",Compare!$B$8,IF(F28="CNY",Compare!$B$9,IF(F28="HKD",Compare!$B$10,1))) | L28: ASSUMPTION ~30k MNT per person, Mongolian insurer
B29: Mobile data eSIM | E29: 10 | F29: USD | G29: =Compare!$B$6 | H29: =E29*G29*IF(F29="USD",Compare!$B$8,IF(F29="CNY",Compare!$B$9,IF(F29="HKD",Compare!$B$10,1))) | I29: =E29 | J29: =Compare!$B$7 | K29: =I29*J29*IF(F29="USD",Compare!$B$8,IF(F29="CNY",Compare!$B$9,IF(F29="HKD",Compare!$B$10,1))) | L29: ASSUMPTION ~$10 pp
B30: Visa | E30: 0 | F30: MNT | G30: =Compare!$B$6 | H30: =E30*G30*IF(F30="USD",Compare!$B$8,IF(F30="CNY",Compare!$B$9,IF(F30="HKD",Compare!$B$10,1))) | I30: =E30 | J30: =Compare!$B$7 | K30: =I30*J30*IF(F30="USD",Compare!$B$8,IF(F30="CNY",Compare!$B$9,IF(F30="HKD",Compare!$B$10,1))) | L30: Mongolian passports: visa-free (mainland China up to 30 days; Hong Kong up to 14 days)
H32: 3 people – UNFUNDED | K32: 4 people – FUNDED ₮12M
G33: University-paid subtotal | H33: =SUM(H9:H22) | K33: =SUM(K9:K22)
G34: Contingency | H34: =H33*Compare!$B$11 | K34: =K33*Compare!$B$11
G35: University-paid total incl. contingency | H35: =H33+H34 | K35: =K33+K34
G36: Funding left (negative = over) | H36: =Compare!$B$12-H35 | K36: =Compare!$B$5-K35
G37: Personal costs – team | H37: =SUM(H24:H30) | K37: =SUM(K24:K30)
G38: Out-of-pocket per person (personal + any overrun) | H38: =(H37+MAX(0,-H36))/Compare!$B$6 | K38: =(K37+MAX(0,-K36))/Compare!$B$7
G39: Whole trip cost (university + personal) | H39: =H35+H37 | K39: =K35+K37
G40: Time in planes & trains | H40: =D10+D11+D13+D14 | K40: =D10+D11+D13+D14
A42: Key facts
A43: Contest | B43: Asia Shenyang Regional, 14–15 Nov 2026 (provisional), Northeastern University Nanhu campus
A44: Why this plan | B44: Cheapest plan without overnight trains: two nights at Dequan (¥304 each), one at Bestay (¥86), MIAT evening flight, G101 at 08:00 reaches Shenyang before the registration desk opens.
...

Sheet Shenyang – Comfort (G-train)
A1: Shenyang – Comfort (G-train)
A2: No sleeper trains: MIAT + high-speed rail out, evening G-train back to Beijing and a hotel night near Chaoyang station; rest day and family room near the venue.
A4: Days in destination (meals & local transport) | B4: 4.5 | C4: 12 Nov morning → midday 16 Nov
A5: Shared inputs are on the Compare sheet. Scroll down for the day-by-day plan and door-to-door travel times.
A7: Category | B7: Item | C7: Date | D7: Travel time | E7: Unit cost (3 ppl) | F7: Currency | G7: Qty (3 ppl) | H7: Total MNT – 3 people | I7: Unit cost (4 ppl) | J7: Qty (4 ppl) | K7: Total MNT – 4 people | L7: Source / notes
A8: PAID BY UNIVERSITY
A9: Flights
B10: MIAT OM223 Ulaanbaatar → Beijing (PEK), 07:30–09:45 | C10: 12 Nov | D10: 0.09375 | E10: 151 | F10: USD | G10: =Compare!$B$6 | H10: =E10*G10*IF(F10="USD",Compare!$B$8,IF(F10="CNY",Compare!$B$9,IF(F10="HKD",Compare!$B$10,1))) | I10: =E10 | J10: =Compare!$B$7 | K10: =I10*J10*IF(F10="USD",Compare!$B$8,IF(F10="CNY",Compare!$B$9,IF(F10="HKD",Compare!$B$10,1))) | L10: Trip.com 30 Sep: MIAT 07:30–09:45 $151 pp (SlickTrip 30 Sep: $154)
B11: Air China Beijing (PEK) → Ulaanbaatar, nonstop 12:55–15:05 | C11: 16 Nov | D11: 0.090277778 | E11: 171 | F11: USD | G11: =Compare!$B$6 | H11: =E11*G11*IF(F11="USD",Compare!$B$8,IF(F11="CNY",Compare!$B$9,IF(F11="HKD",Compare!$B$10,1))) | I11: =E11 | J11: =Compare!$B$7 | K11: =I11*J11*IF(F11="USD",Compare!$B$8,IF(F11="CNY",Compare!$B$9,IF(F11="HKD",Compare!$B$10,1))) | L11: Trip.com 30 Sep: Air China nonstop $171 pp (MIAT OM224 11:30 was $194 on Trip.com, $196.33 on SlickTrip)
A12: Trains
B13: High-speed rail Beijing Chaoyang 12:19 → Shenyang North 14:48 (G149), 2nd class | C13: 12 Nov (midday) | D13: 0.10347222 | E13: 369 | F13: CNY | G13: =Compare!$B$6 | H13: =E13*G13*IF(F13="USD",Compare!$B$8,IF(F13="CNY",Compare!$B$9,IF(F13="HKD",Compare!$B$10,1))) | I13: =E13 | J13: =Compare!$B$7 | K13: =I13*J13*IF(F13="USD",Compare!$B$8,IF(F13="CNY",Compare!$B$9,IF(F13="HKD",Compare!$B$10,1))) | L13: 12306 (queried 10 Oct for 20 Oct; fares fixed): G149 ¥369; G3539 11:43 → 15:34 ¥355; slower 3 h 15–3 h 35 trains ¥296–317. MIAT lands 09:45, so a ~12:00 train is realistic (the old ¥339 in Shenyang – Comfort is not on the 12306 list)
B14: High-speed rail Shenyang North 19:51 → Beijing Chaoyang 22:30 (G142), 2nd class | C14: 15 Nov (evening) | D14: 0.11041667 | E14: 268 | F14: CNY | G14: =Compare!$B$6 | H14: =E14*G14*IF(F14="USD",Compare!$B$8,IF(F14="CNY",Compare!$B$9,IF(F14="HKD",Compare!$B$10,1))) | I14: =E14 | J14: =Compare!$B$7 | K14: =I14*J14*IF(F14="USD",Compare!$B$8,IF(F14="CNY",Compare!$B$9,IF(F14="HKD",Compare!$B$10,1))) | L14: 12306 (queried 10 Oct for 20 Oct; fares fixed): G142 / G156 (Shenyang stn 19:05) / G3522 19:21 → 22:36 ¥268; G122 / G126 ¥344. Awards end ~17:00, so 19:51 leaves a safe margin
A15: Accommodation
B16: Shenyang RiCH Hotel, Sanhao St (~1.3 km to NEU Nanhu; Family Room sleeps 4, so one room for 3 or 4) | C16: 12–15 Nov (3 nights) | E16: 325.33 | F16: CNY | G16: 3 | H16: =E16*G16*IF(F16="USD",Compare!$B$8,IF(F16="CNY",Compare!$B$9,IF(F16="HKD",Compare!$B$10,1))) | I16: 325.33 | J16: 3 | K16: =I16*J16*IF(F16="USD",Compare!$B$8,IF(F16="CNY",Compare!$B$9,IF(F16="HKD",Compare!$B$10,1))) | L16: Trip.com 1 Oct: Family Room ¥976 for 3 nights, same price for 3 or 4 adults; rated 9.6 (1,802 reviews)
B17: Dequan Railway Station Hotel, Beijing (~1 km from Beijing Chaoyang station; 3 ppl 1 room; 4 ppl 2 rooms) | C17: 15 Nov (1 night) | E17: 304 | F17: CNY | G17: 1 | H17: =E17*G17*IF(F17="USD",Compare!$B$8,IF(F17="CNY",Compare!$B$9,IF(F17="HKD",Compare!$B$10,1))) | I17: 608 | J17: 1 | K17: =I17*J17*IF(F17="USD",Compare!$B$8,IF(F17="CNY",Compare!$B$9,IF(F17="HKD",Compare!$B$10,1))) | L17: Booking.com 9 Oct: ¥304 for 3 adults, 1 room per night; rated 8.7 (65 reviews). 4 ppl: ASSUMPTION 2 × ¥304 (rooms not searched)
A18: Meals & local transport
B19: Meals | C19: in destination | E19: 80 | F19: CNY | G19: =Compare!$B$6*$B$4 | H19: =E19*G19*IF(F19="USD",Compare!$B$8,IF(F19="CNY",Compare!$B$9,IF(F19="HKD",Compare!$B$10,1))) | I19: =E19 | J19: =Compare!$B$7*$B$4 | K19: =I19*J19*IF(F19="USD",Compare!$B$8,IF(F19="CNY",Compare!$B$9,IF(F19="HKD",Compare!$B$10,1))) | L19: ASSUMPTION 80 CNY/person/day; hosts usually provide some meals on contest days
B20: Local transport (metro, taxis) | C20: in destination | E20: 30 | F20: CNY | G20: =Compare!$B$6*$B$4 | H20: =E20*G20*IF(F20="USD",Compare!$B$8,IF(F20="CNY",Compare!$B$9,IF(F20="HKD",Compare!$B$10,1))) | I20: =E20 | J20: =Compare!$B$7*$B$4 | K20: =I20*J20*IF(F20="USD",Compare!$B$8,IF(F20="CNY",Compare!$B$9,IF(F20="HKD",Compare!$B$10,1))) | L20: ASSUMPTION 30 CNY/person/day
B21: Taxi PEK → Beijing Chaoyang station | C21: 12 Nov | E21: 120 | F21: CNY | G21: 1 | H21: =E21*G21*IF(F21="USD",Compare!$B$8,IF(F21="CNY",Compare!$B$9,IF(F21="HKD",Compare!$B$10,1))) | I21: =E21 | J21: 1 | K21: =I21*J21*IF(F21="USD",Compare!$B$8,IF(F21="CNY",Compare!$B$9,IF(F21="HKD",Compare!$B$10,1))) | L21: ASSUMPTION ~120 CNY per car, ~40 km (4 ppl may need an XL car)
B22: Taxi Dequan hotel → PEK | C22: 16 Nov | E22: 120 | F22: CNY | G22: 1 | H22: =E22*G22*IF(F22="USD",Compare!$B$8,IF(F22="CNY",Compare!$B$9,IF(F22="HKD",Compare!$B$10,1))) | I22: =E22 | J22: 1 | K22: =I22*J22*IF(F22="USD",Compare!$B$8,IF(F22="CNY",Compare!$B$9,IF(F22="HKD",Compare!$B$10,1))) | L22: ASSUMPTION ~120 CNY per car, ~35 km, leave ~09:00
A23: PAID PERSONALLY (university won't cover)
A24: Contest fee
B25: Shenyang regional registration fee (per team) | C25: pay by mid-Oct | E25: 1500 | F25: CNY | G25: 1 | H25: =E25*G25*IF(F25="USD",Compare!$B$8,IF(F25="CNY",Compare!$B$9,IF(F25="HKD",Compare!$B$10,1))) | I25: =E25 | J25: 1 | K25: =I25*J25*IF(F25="USD",Compare!$B$8,IF(F25="CNY",Compare!$B$9,IF(F25="HKD",Compare!$B$10,1))) | L25: ASSUMPTION: 1,500 CNY/team like recent EC regionals; 2026 Shenyang invitation not seen
A26: Other
B27: Taxi to/from Chinggis Khaan airport (UB), per trip | C27: out & back | D27: 0.041666667 | E27: 100000 | F27: MNT | G27: 2 | H27: =E27*G27*IF(F27="USD",Compare!$B$8,IF(F27="CNY",Compare!$B$9,IF(F27="HKD",Compare!$B$10,1))) | I27: =E27 | J27: 2 | K27: =I27*J27*IF(F27="USD",Compare!$B$8,IF(F27="CNY",Compare!$B$9,IF(F27="HKD",Compare!$B$10,1))) | L27: ASSUMPTION 100k MNT per trip for the group
B28: Travel medical insurance | E28: 30000 | F28: MNT | G28: =Compare!$B$6 | H28: =E28*G28*IF(F28="USD",Compare!$B$8,IF(F28="CNY",Compare!$B$9,IF(F28="HKD",Compare!$B$10,1))) | I28: =E28 | J28: =Compare!$B$7 | K28: =I28*J28*IF(F28="USD",Compare!$B$8,IF(F28="CNY",Compare!$B$9,IF(F28="HKD",Compare!$B$10,1))) | L28: ASSUMPTION ~30k MNT per person, Mongolian insurer
B29: Mobile data eSIM | E29: 10 | F29: USD | G29: =Compare!$B$6 | H29: =E29*G29*IF(F29="USD",Compare!$B$8,IF(F29="CNY",Compare!$B$9,IF(F29="HKD",Compare!$B$10,1))) | I29: =E29 | J29: =Compare!$B$7 | K29: =I29*J29*IF(F29="USD",Compare!$B$8,IF(F29="CNY",Compare!$B$9,IF(F29="HKD",Compare!$B$10,1))) | L29: ASSUMPTION ~$10 pp
B30: Visa | E30: 0 | F30: MNT | G30: =Compare!$B$6 | H30: =E30*G30*IF(F30="USD",Compare!$B$8,IF(F30="CNY",Compare!$B$9,IF(F30="HKD",Compare!$B$10,1))) | I30: =E30 | J30: =Compare!$B$7 | K30: =I30*J30*IF(F30="USD",Compare!$B$8,IF(F30="CNY",Compare!$B$9,IF(F30="HKD",Compare!$B$10,1))) | L30: Mongolian passports: visa-free (mainland China up to 30 days; Hong Kong up to 14 days)
H32: 3 people – UNFUNDED | K32: 4 people – FUNDED ₮12M
G33: University-paid subtotal | H33: =SUM(H9:H22) | K33: =SUM(K9:K22)
G34: Contingency | H34: =H33*Compare!$B$11 | K34: =K33*Compare!$B$11
G35: University-paid total incl. contingency | H35: =H33+H34 | K35: =K33+K34
G36: Funding left (negative = over) | H36: =Compare!$B$12-H35 | K36: =Compare!$B$5-K35
G37: Personal costs – team | H37: =SUM(H24:H30) | K37: =SUM(K24:K30)
G38: Out-of-pocket per person (personal + any overrun) | H38: =(H37+MAX(0,-H36))/Compare!$B$6 | K38: =(K37+MAX(0,-K36))/Compare!$B$7
G39: Whole trip cost (university + personal) | H39: =H35+H37 | K39: =K35+K37
G40: Time in planes & trains | H40: =D10+D11+D13+D14 | K40: =D10+D11+D13+D14
A42: Key facts
A43: Contest | B43: Asia Shenyang Regional, 14–15 Nov 2026 (provisional), Northeastern University Nanhu campus
A44: Why this plan | B44: Same rest day and hotel as Shenyang – Comfort, but no overnight train: you sleep in a bed both nights and the evening G-train is cheap (¥268). Fits a late closing ceremony (train 19:51).
...

Sheet Shenyang – Sleep first
A1: Shenyang – Sleep first
A2: Sleep first before the contest, cheapest after: no early alarm (Air China 11:50), three nights in the same quiet hotel next to the venue with a bed each; hard-seat night train + cheapest flight home.
A4: Days in destination (meals & local transport) | B4: 4 | C4: 12 Nov afternoon → 16 Nov midday
A5: Shared inputs are on the Compare sheet. Scroll down for the day-by-day plan and door-to-door travel times.
A7: Category | B7: Item | C7: Date | D7: Travel time | E7: Unit cost (3 ppl) | F7: Currency | G7: Qty (3 ppl) | H7: Total MNT – 3 people | I7: Unit cost (4 ppl) | J7: Qty (4 ppl) | K7: Total MNT – 4 people | L7: Source / notes
A8: PAID BY UNIVERSITY
A9: Flights
B10: Air China CA902 Ulaanbaatar 11:50 → Beijing Capital (PEK) 13:55, nonstop, checked bag included | C10: 12 Nov | D10: 0.086805556 | E10: 1291 | F10: CNY | G10: =Compare!$B$6 | H10: =E10*G10*IF(F10="USD",Compare!$B$8,IF(F10="CNY",Compare!$B$9,IF(F10="HKD",Compare!$B$10,1))) | I10: =E10 | J10: =Compare!$B$7 | K10: =I10*J10*IF(F10="USD",Compare!$B$8,IF(F10="CNY",Compare!$B$9,IF(F10="HKD",Compare!$B$10,1))) | L10: Ctrip 22 Oct: ¥1,291 pp incl. tax – cheapest of 5 sources (Kiwi $200, Trip.com $203, SlickTrip $316 on 13 Nov, Google Flights unpriced). MIAT OM223 07:30 is ¥1,096 on Ctrip / $167 Kiwi / $172 Google / $154 SlickTrip but means a ~04:00 wake-up. Ctrip needs a Ctrip account (Alipay or a foreign card); Trip.com $203 is the fallback.
B11: Air China CA955 Beijing Capital (PEK) 12:55 → Ulaanbaatar 15:05, nonstop | C11: 16 Nov | D11: 0.090277778 | E11: 171 | F11: USD | G11: =Compare!$B$6 | H11: =E11*G11*IF(F11="USD",Compare!$B$8,IF(F11="CNY",Compare!$B$9,IF(F11="HKD",Compare!$B$10,1))) | I11: =E11 | J11: =Compare!$B$7 | K11: =I11*J11*IF(F11="USD",Compare!$B$8,IF(F11="CNY",Compare!$B$9,IF(F11="HKD",Compare!$B$10,1))) | L11: Trip.com 22 Oct: US$171 pp, cheapest that day (MIAT OM224 11:30 US$193 on Trip.com / $176 on SlickTrip; Air China 08:25 $215; Capital + Hunnu via Erenhot $196)
A12: Trains
B13: High-speed rail G153 Beijing Chaoyang 17:27 → Shenyang 20:04, 2nd class | C13: 12 Nov (evening) | D13: 0.10902778 | E13: 369 | F13: CNY | G13: =Compare!$B$6 | H13: =E13*G13*IF(F13="USD",Compare!$B$8,IF(F13="CNY",Compare!$B$9,IF(F13="HKD",Compare!$B$10,1))) | I13: =E13 | J13: =Compare!$B$7 | K13: =I13*J13*IF(F13="USD",Compare!$B$8,IF(F13="CNY",Compare!$B$9,IF(F13="HKD",Compare!$B$10,1))) | L13: 12306 (queried 22 Oct for 5 Nov; fares fixed): ¥369. ChinaTicketOnline confirms G153 on 12 Nov, on sale 29 Oct 10:00. Leaves 3 h 30 min after landing; if the flight is on time, change at the station to G141 16:00 → Shenyang North 18:29 (¥369). Later trains: G155 18:35 / G143 18:48 (¥369–383). Ctrip train list (22 Oct, for 12 Nov) shows the same fares; 12go.asia resells at ~$90 for 1st class.
B14: Overnight train K28 Shenyang 22:24 → Beijing 08:40, hard seat (after the contest) | C14: 15 Nov (night) | D14: 0.42777778 | E14: 112 | F14: CNY | G14: =Compare!$B$6 | H14: =E14*G14*IF(F14="USD",Compare!$B$8,IF(F14="CNY",Compare!$B$9,IF(F14="HKD",Compare!$B$10,1))) | I14: =E14 | J14: =Compare!$B$7 | K14: =I14*J14*IF(F14="USD",Compare!$B$8,IF(F14="CNY",Compare!$B$9,IF(F14="HKD",Compare!$B$10,1))) | L14: 12306 (5 Nov query): hard seat ¥112 (hard sleeper ¥194). Cheapest train that still makes the 12:55 flight (K96 23:39 ¥102 arrives 11:19 – too late). Lie-flat upgrade: K54 Shenyang North 22:00 → 06:58 hard sleeper ¥171 (+¥59 pp). On sale 1 Nov 09:30 (ChinaTicketOnline confirms 15 Nov).
A15: Accommodation
B16: NEU International Hotel, 80 Wenti West Rd (~580 m to NEU Nanhu): 2 Superior Twin rooms, 38 m², floors 5–10 – a bed each | C16: 12–15 Nov (3 nights) | E16: 796 | F16: CNY | G16: 3 | H16: =E16*G16*IF(F16="USD",Compare!$B$8,IF(F16="CNY",Compare!$B$9,IF(F16="HKD",Compare!$B$10,1))) | I16: 796 | J16: 3 | K16: =I16*J16*IF(F16="USD",Compare!$B$8,IF(F16="CNY",Compare!$B$9,IF(F16="HKD",Compare!$B$10,1))) | L16: Trip.com 22 Oct: ¥2,388 for 2 rooms × 3 nights incl. taxes, free cancellation, pay at hotel; same price for 3 or 4 adults. 9.7 from 1,998 reviews (no negative review in 2 years; campus/river views). Shown as a 30% 'Surprise Savings' rate (list ¥547 per room-night = ¥3,282) – book soon.
A17: Meals & local transport
